Workbook

Sheet LCS Bahrain
A2: =TODAY() -> 46066 | R2: =YEAR('LCS Sasebo'!R10) -> 2026 | S2: =YEAR('LCS Sasebo'!S10) -> 2026 | T2: =YEAR('LCS Sasebo'!T10) -> 2026 | U2: =YEAR('LCS Sasebo'!U10) -> 2026 | V2: =YEAR('LCS Sasebo'!V10) -> 2026 | W2: =YEAR('LCS Sasebo'!W10) -> 2026 | X2: =YEAR('LCS Sasebo'!X10) -> 2026 | Y2: =YEAR('LCS Sasebo'!Y10) -> 2026 | ... CL2: =YEAR('LCS Sasebo'!CL10) -> 2032
A3: SHIP | B3: XO TL | C3: CO TL | D3: TOL | E3: P/L | G3: DAYS | H3: XO | J3: T.O. | L3: COC | N3: CO | P3: COC | R3: =RIGHT(YEAR('LCS Sasebo'!R10),2)+(MONTH('LCS Sasebo'!R10)>=10)&"-"&INT(1+MOD(MONTH('LCS Sasebo'!R10)-10,12)/3) -> NaN | S3: =RIGHT(YEAR('LCS Sasebo'!S10),2)+(MONTH('LCS Sasebo'!S10)>=10)&"-"&INT(1+MOD(MONTH('LCS Sasebo'!S10)-10,12)/3) -> NaN | T3: =RIGHT(YEAR('LCS Sasebo'!T10),2)+(MONTH('LCS Sasebo'!T10)>=10)&"-"&INT(1+MOD(MONTH('LCS Sasebo'!T10)-10,12)/3) -> NaN | U3: =RIGHT(YEAR('LCS Sasebo'!U10),2)+(MONTH('LCS Sasebo'!U10)>=10)&"-"&INT(1+MOD(MONTH('LCS Sasebo'!U10)-10,12)/3) -> NaN | V3: =RIGHT(YEAR('LCS Sasebo'!V10),2)+(MONTH('LCS Sasebo'!V10)>=10)&"-"&INT(1+MOD(MONTH('LCS Sasebo'!V10)-10,12)/3) -> NaN | W3: =RIGHT(YEAR('LCS Sasebo'!W10),2)+(MONTH('LCS Sasebo'!W10)>=10)&"-"&INT(1+MOD(MONTH('LCS Sasebo'!W10)-10,12)/3) -> NaN | X3: =RIGHT(YEAR('LCS Sasebo'!X10),2)+(MONTH('LCS Sasebo'!X10)>=10)&"-"&INT(1+MOD(MONTH('LCS Sasebo'!X10)-10,12)/3) -> NaN | Y3: =RIGHT(YEAR('LCS Sasebo'!Y10),2)+(MONTH('LCS Sasebo'!Y10)>=10)&"-"&INT(1+MOD(MONTH('LCS Sasebo'!Y10)-10,12)/3) -> NaN | ... CL3: =RIGHT(YEAR('LCS Sasebo'!CL10),2)+(MONTH('LCS Sasebo'!CL10)>=10)&"-"&INT(1+MOD(MONTH('LCS Sasebo'!CL10)-10,12)/3) -> NaN
A4: CHARLESTON (LCS 18) - 20156 | R4: ='LCS San Diego'!$A$2-DAY('LCS San Diego'!$A$2)+1 -> 46054 | S4: =DATE(YEAR(R4),MONTH(R4)+1,DAY(R4)) -> 46082 | T4: =DATE(YEAR(S4),MONTH(S4)+1,DAY(S4)) -> 46113 | U4: =DATE(YEAR(T4),MONTH(T4)+1,DAY(T4)) -> 46143 | V4: =DATE(YEAR(U4),MONTH(U4)+1,DAY(U4)) -> 46174 | W4: =DATE(YEAR(V4),MONTH(V4)+1,DAY(V4)) -> 46204 | X4: =DATE(YEAR(W4),MONTH(W4)+1,DAY(W4)) -> 46235 | Y4: =DATE(YEAR(X4),MONTH(X4)+1,DAY(X4)) -> 46266 | Z4: =DATE(YEAR(Y4),MONTH(Y4)+1,DAY(Y4)) -> 46296 | ... CL4: =DATE(YEAR(CK4),MONTH(CK4)+1,DAY(CK4)) -> 48245
A5: Wang, Nellie (CHS single crew CO)(COC NOV24) | B5: 16 | C5: 16 | D5: 1 | G5: =F5-E5 -> 0 | H5: 44378 | I5: =IF(H5="",0,DATE(YEAR(H5),MONTH(H5)+B5,DAY(H5))) -> 44866 | J5: =IF(I5="","",(DATE(YEAR(I5),MONTH(I5)+1,DAY(I5)))) -> 44896 | K5: =IF(J5="","",(DATE(YEAR(J5),MONTH(J5)+D5,DAY(J5)))) -> 44927 | L5: 44980 | M5: 44980 | N5: 44980 | O5: 45620 | P5: 45620 | Q5: 45620 | R5: =IF((AND($E5<='LCS San Diego'!R$4,$F5>='LCS San Diego'!R$4)),"P/L",IF((AND($H5<='LCS San Diego'!R$4,$I5>='LCS San Diego'!R$4)),"XO",IF((AND($J5<='LCS San Diego'!R$4,$K5>='LCS San Diego'!R$4)),"3",IF((AND($L5<='LCS San Diego'!R$4,$M5>='LCS San Diego'!R$4)),"C",IF((AND($N5<='LCS San Diego'!R$4,$O5>='LCS San Diego'!R$4)),"CO",IF((AND($P5<='LCS San Diego'!R$4,$Q5>='LCS San Diego'!R$4)),"C",0)))))) -> 0 | S5: =IF((AND($E5<='LCS San Diego'!S$4,$F5>='LCS San Diego'!S$4)),"P/L",IF((AND($H5<='LCS San Diego'!S$4,$I5>='LCS San Diego'!S$4)),"XO",IF((AND($J5<='LCS San Diego'!S$4,$K5>='LCS San Diego'!S$4)),"3",IF((AND($L5<='LCS San Diego'!S$4,$M5>='LCS San Diego'!S$4)),"C",IF((AND($N5<='LCS San Diego'!S$4,$O5>='LCS San Diego'!S$4)),"CO",IF((AND($P5<='LCS San Diego'!S$4,$Q5>='LCS San Diego'!S$4)),"C",0)))))) -> 0 | T5: =IF((AND($E5<='LCS San Diego'!T$4,$F5>='LCS San Diego'!T$4)),"P/L",IF((AND($H5<='LCS San Diego'!T$4,$I5>='LCS San Diego'!T$4)),"XO",IF((AND($J5<='LCS San Diego'!T$4,$K5>='LCS San Diego'!T$4)),"3",IF((AND($L5<='LCS San Diego'!T$4,$M5>='LCS San Diego'!T$4)),"C",IF((AND($N5<='LCS San Diego'!T$4,$O5>='LCS San Diego'!T$4)),"CO",IF((AND($P5<='LCS San Diego'!T$4,$Q5>='LCS San Diego'!T$4)),"C",0)))))) -> 0 | U5: =IF((AND($E5<='LCS San Diego'!U$4,$F5>='LCS San Diego'!U$4)),"P/L",IF((AND($H5<='LCS San Diego'!U$4,$I5>='LCS San Diego'!U$4)),"XO",IF((AND($J5<='LCS San Diego'!U$4,$K5>='LCS San Diego'!U$4)),"3",IF((AND($L5<='LCS San Diego'!U$4,$M5>='LCS San Diego'!U$4)),"C",IF((AND($N5<='LCS San Diego'!U$4,$O5>='LCS San Diego'!U$4)),"CO",IF((AND($P5<='LCS San Diego'!U$4,$Q5>='LCS San Diego'!U$4)),"C",0)))))) -> 0 | V5: =IF((AND($E5<='LCS San Diego'!V$4,$F5>='LCS San Diego'!V$4)),"P/L",IF((AND($H5<='LCS San Diego'!V$4,$I5>='LCS San Diego'!V$4)),"XO",IF((AND($J5<='LCS San Diego'!V$4,$K5>='LCS San Diego'!V$4)),"3",IF((AND($L5<='LCS San Diego'!V$4,$M5>='LCS San Diego'!V$4)),"C",IF((AND($N5<='LCS San Diego'!V$4,$O5>='LCS San Diego'!V$4)),"CO",IF((AND($P5<='LCS San Diego'!V$4,$Q5>='LCS San Diego'!V$4)),"C",0)))))) -> 0 | W5: =IF((AND($E5<='LCS San Diego'!W$4,$F5>='LCS San Diego'!W$4)),"P/L",IF((AND($H5<='LCS San Diego'!W$4,$I5>='LCS San Diego'!W$4)),"XO",IF((AND($J5<='LCS San Diego'!W$4,$K5>='LCS San Diego'!W$4)),"3",IF((AND($L5<='LCS San Diego'!W$4,$M5>='LCS San Diego'!W$4)),"C",IF((AND($N5<='LCS San Diego'!W$4,$O5>='LCS San Diego'!W$4)),"CO",IF((AND($P5<='LCS San Diego'!W$4,$Q5>='LCS San Diego'!W$4)),"C",0)))))) -> 0 | X5: =IF((AND($E5<='LCS San Diego'!X$4,$F5>='LCS San Diego'!X$4)),"P/L",IF((AND($H5<='LCS San Diego'!X$4,$I5>='LCS San Diego'!X$4)),"XO",IF((AND($J5<='LCS San Diego'!X$4,$K5>='LCS San Diego'!X$4)),"3",IF((AND($L5<='LCS San Diego'!X$4,$M5>='LCS San Diego'!X$4)),"C",IF((AND($N5<='LCS San Diego'!X$4,$O5>='LCS San Diego'!X$4)),"CO",IF((AND($P5<='LCS San Diego'!X$4,$Q5>='LCS San Diego'!X$4)),"C",0)))))) -> 0 | Y5: =IF((AND($E5<='LCS San Diego'!Y$4,$F5>='LCS San Diego'!Y$4)),"P/L",IF((AND($H5<='LCS San Diego'!Y$4,$I5>='LCS San Diego'!Y$4)),"XO",IF((AND($J5<='LCS San Diego'!Y$4,$K5>='LCS San Diego'!Y$4)),"3",IF((AND($L5<='LCS San Diego'!Y$4,$M5>='LCS San Diego'!Y$4)),"C",IF((AND($N5<='LCS San Diego'!Y$4,$O5>='LCS San Diego'!Y$4)),"CO",IF((AND($P5<='LCS San Diego'!Y$4,$Q5>='LCS San Diego'!Y$4)),"C",0)))))) -> 0 | ... CL5: =IF((AND($E5<='LCS San Diego'!CL$4,$F5>='LCS San Diego'!CL$4)),"P/L",IF((AND($H5<='LCS San Diego'!CL$4,$I5>='LCS San Diego'!CL$4)),"XO",IF((AND($J5<='LCS San Diego'!CL$4,$K5>='LCS San Diego'!CL$4)),"3",IF((AND($L5<='LCS San Diego'!CL$4,$M5>='LCS San Diego'!CL$4)),"C",IF((AND($N5<='LCS San Diego'!CL$4,$O5>='LCS San Diego'!CL$4)),"CO",IF((AND($P5<='LCS San Diego'!CL$4,$Q5>='LCS San Diego'!CL$4)),"C",0)))))) -> 0
A6: Gray, Meghan (XO/CO) (CHS single crew XO/CO) | B6: 17 | C6: 16 | D6: 1 | G6: =F6-E6 -> 0 | H6: 44887 | I6: =IF(H6="",0,DATE(YEAR(H6),MONTH(H6)+B6,DAY(H6))) -> 45404 | J6: =IF(I6="","",(DATE(YEAR(I6),MONTH(I6)+1,DAY(I6)))) -> 45434 | K6: =IF(J6="","",(DATE(YEAR(J6),MONTH(J6)+D6,DAY(J6)))) -> 45465 | L6: 45620 | M6: =IF(N6="","",DATE(YEAR(L6),MONTH(L6),DAY(L6))) -> 45620 | N6: 45620 | O6: 46168 | P6: 46168 | Q6: =IF(O6="","",DATE(YEAR(P6),MONTH(P6),DAY(P6))) -> 46168 | R6: =IF((AND($E6<='LCS San Diego'!R$4,$F6>='LCS San Diego'!R$4)),"P/L",IF((AND($H6<='LCS San Diego'!R$4,$I6>='LCS San Diego'!R$4)),"XO",IF((AND($J6<='LCS San Diego'!R$4,$K6>='LCS San Diego'!R$4)),"3",IF((AND($L6<='LCS San Diego'!R$4,$M6>='LCS San Diego'!R$4)),"C",IF((AND($N6<='LCS San Diego'!R$4,$O6>='LCS San Diego'!R$4)),"CO",IF((AND($P6<='LCS San Diego'!R$4,$Q6>='LCS San Diego'!R$4)),"C",0)))))) -> CO | S6: =IF((AND($E6<='LCS San Diego'!S$4,$F6>='LCS San Diego'!S$4)),"P/L",IF((AND($H6<='LCS San Diego'!S$4,$I6>='LCS San Diego'!S$4)),"XO",IF((AND($J6<='LCS San Diego'!S$4,$K6>='LCS San Diego'!S$4)),"3",IF((AND($L6<='LCS San Diego'!S$4,$M6>='LCS San Diego'!S$4)),"C",IF((AND($N6<='LCS San Diego'!S$4,$O6>='LCS San Diego'!S$4)),"CO",IF((AND($P6<='LCS San Diego'!S$4,$Q6>='LCS San Diego'!S$4)),"C",0)))))) -> CO | T6: =IF((AND($E6<='LCS San Diego'!T$4,$F6>='LCS San Diego'!T$4)),"P/L",IF((AND($H6<='LCS San Diego'!T$4,$I6>='LCS San Diego'!T$4)),"XO",IF((AND($J6<='LCS San Diego'!T$4,$K6>='LCS San Diego'!T$4)),"3",IF((AND($L6<='LCS San Diego'!T$4,$M6>='LCS San Diego'!T$4)),"C",IF((AND($N6<='LCS San Diego'!T$4,$O6>='LCS San Diego'!T$4)),"CO",IF((AND($P6<='LCS San Diego'!T$4,$Q6>='LCS San Diego'!T$4)),"C",0)))))) -> CO | U6: =IF((AND($E6<='LCS San Diego'!U$4,$F6>='LCS San Diego'!U$4)),"P/L",IF((AND($H6<='LCS San Diego'!U$4,$I6>='LCS San Diego'!U$4)),"XO",IF((AND($J6<='LCS San Diego'!U$4,$K6>='LCS San Diego'!U$4)),"3",IF((AND($L6<='LCS San Diego'!U$4,$M6>='LCS San Diego'!U$4)),"C",IF((AND($N6<='LCS San Diego'!U$4,$O6>='LCS San Diego'!U$4)),"CO",IF((AND($P6<='LCS San Diego'!U$4,$Q6>='LCS San Diego'!U$4)),"C",0)))))) -> CO | V6: =IF((AND($E6<='LCS San Diego'!V$4,$F6>='LCS San Diego'!V$4)),"P/L",IF((AND($H6<='LCS San Diego'!V$4,$I6>='LCS San Diego'!V$4)),"XO",IF((AND($J6<='LCS San Diego'!V$4,$K6>='LCS San Diego'!V$4)),"3",IF((AND($L6<='LCS San Diego'!V$4,$M6>='LCS San Diego'!V$4)),"C",IF((AND($N6<='LCS San Diego'!V$4,$O6>='LCS San Diego'!V$4)),"CO",IF((AND($P6<='LCS San Diego'!V$4,$Q6>='LCS San Diego'!V$4)),"C",0)))))) -> 0 | W6: =IF((AND($E6<='LCS San Diego'!W$4,$F6>='LCS San Diego'!W$4)),"P/L",IF((AND($H6<='LCS San Diego'!W$4,$I6>='LCS San Diego'!W$4)),"XO",IF((AND($J6<='LCS San Diego'!W$4,$K6>='LCS San Diego'!W$4)),"3",IF((AND($L6<='LCS San Diego'!W$4,$M6>='LCS San Diego'!W$4)),"C",IF((AND($N6<='LCS San Diego'!W$4,$O6>='LCS San Diego'!W$4)),"CO",IF((AND($P6<='LCS San Diego'!W$4,$Q6>='LCS San Diego'!W$4)),"C",0)))))) -> 0 | X6: =IF((AND($E6<='LCS San Diego'!X$4,$F6>='LCS San Diego'!X$4)),"P/L",IF((AND($H6<='LCS San Diego'!X$4,$I6>='LCS San Diego'!X$4)),"XO",IF((AND($J6<='LCS San Diego'!X$4,$K6>='LCS San Diego'!X$4)),"3",IF((AND($L6<='LCS San Diego'!X$4,$M6>='LCS San Diego'!X$4)),"C",IF((AND($N6<='LCS San Diego'!X$4,$O6>='LCS San Diego'!X$4)),"CO",IF((AND($P6<='LCS San Diego'!X$4,$Q6>='LCS San Diego'!X$4)),"C",0)))))) -> 0 | Y6: =IF((AND($E6<='LCS San Diego'!Y$4,$F6>='LCS San Diego'!Y$4)),"P/L",IF((AND($H6<='LCS San Diego'!Y$4,$I6>='LCS San Diego'!Y$4)),"XO",IF((AND($J6<='LCS San Diego'!Y$4,$K6>='LCS San Diego'!Y$4)),"3",IF((AND($L6<='LCS San Diego'!Y$4,$M6>='LCS San Diego'!Y$4)),"C",IF((AND($N6<='LCS San Diego'!Y$4,$O6>='LCS San Diego'!Y$4)),"CO",IF((AND($P6<='LCS San Diego'!Y$4,$Q6>='LCS San Diego'!Y$4)),"C",0)))))) -> 0 | ... CL6: =IF((AND($E6<='LCS San Diego'!CL$4,$F6>='LCS San Diego'!CL$4)),"P/L",IF((AND($H6<='LCS San Diego'!CL$4,$I6>='LCS San Diego'!CL$4)),"XO",IF((AND($J6<='LCS San Diego'!CL$4,$K6>='LCS San Diego'!CL$4)),"3",IF((AND($L6<='LCS San Diego'!CL$4,$M6>='LCS San Diego'!CL$4)),"C",IF((AND($N6<='LCS San Diego'!CL$4,$O6>='LCS San Diego'!CL$4)),"CO",IF((AND($P6<='LCS San Diego'!CL$4,$Q6>='LCS San Diego'!CL$4)),"C",0)))))) -> 0
A7: Hooge, Daniel (XO/CO) (CHS single crew PXO)(SEP24) | B7: 17 | C7: 16 | D7: 1 | G7: =F7-E7 -> 0 | H7: 45559 | I7: =IF(H7="",0,DATE(YEAR(H7),MONTH(H7)+B7,DAY(H7))) -> 46077 | J7: =IF(I7="","",(DATE(YEAR(I7),MONTH(I7)+1,DAY(I7)))) -> 46105 | K7: =IF(J7="","",(DATE(YEAR(J7),MONTH(J7)+D7,DAY(J7)))) -> 46136 | L7: =IF(N7="","",DATE(YEAR(N7), MONTH(N7)-1,DAY(N7))) -> 46166 | M7: =IF(N7="","",DATE(YEAR(L7),MONTH(L7),DAY(L7))) -> 46166 | N7: =IF(K7="","",(DATE(YEAR(K7),MONTH(K7)+2,DAY(K7)))) -> 46197 | O7: =IF(N7="","",(DATE(YEAR(N7),MONTH(N7)+C7,DAY(N7)))) -> 46684 | P7: =IF(O7="","",DATE(YEAR(O7), MONTH(O7)+1,DAY(O7))) -> 46715 | Q7: =IF(O7="","",DATE(YEAR(P7),MONTH(P7),DAY(P7))) -> 46715 | R7: =IF((AND($E7<='LCS San Diego'!R$4,$F7>='LCS San Diego'!R$4)),"P/L",IF((AND($H7<='LCS San Diego'!R$4,$I7>='LCS San Diego'!R$4)),"XO",IF((AND($J7<='LCS San Diego'!R$4,$K7>='LCS San Diego'!R$4)),"3",IF((AND($L7<='LCS San Diego'!R$4,$M7>='LCS San Diego'!R$4)),"C",IF((AND($N7<='LCS San Diego'!R$4,$O7>='LCS San Diego'!R$4)),"CO",IF((AND($P7<='LCS San Diego'!R$4,$Q7>='LCS San Diego'!R$4)),"C",0)))))) -> XO | S7: =IF((AND($E7<='LCS San Diego'!S$4,$F7>='LCS San Diego'!S$4)),"P/L",IF((AND($H7<='LCS San Diego'!S$4,$I7>='LCS San Diego'!S$4)),"XO",IF((AND($J7<='LCS San Diego'!S$4,$K7>='LCS San Diego'!S$4)),"3",IF((AND($L7<='LCS San Diego'!S$4,$M7>='LCS San Diego'!S$4)),"C",IF((AND($N7<='LCS San Diego'!S$4,$O7>='LCS San Diego'!S$4)),"CO",IF((AND($P7<='LCS San Diego'!S$4,$Q7>='LCS San Diego'!S$4)),"C",0)))))) -> 0 | T7: =IF((AND($E7<='LCS San Diego'!T$4,$F7>='LCS San Diego'!T$4)),"P/L",IF((AND($H7<='LCS San Diego'!T$4,$I7>='LCS San Diego'!T$4)),"XO",IF((AND($J7<='LCS San Diego'!T$4,$K7>='LCS San Diego'!T$4)),"3",IF((AND($L7<='LCS San Diego'!T$4,$M7>='LCS San Diego'!T$4)),"C",IF((AND($N7<='LCS San Diego'!T$4,$O7>='LCS San Diego'!T$4)),"CO",IF((AND($P7<='LCS San Diego'!T$4,$Q7>='LCS San Diego'!T$4)),"C",0)))))) -> 3 | U7: =IF((AND($E7<='LCS San Diego'!U$4,$F7>='LCS San Diego'!U$4)),"P/L",IF((AND($H7<='LCS San Diego'!U$4,$I7>='LCS San Diego'!U$4)),"XO",IF((AND($J7<='LCS San Diego'!U$4,$K7>='LCS San Diego'!U$4)),"3",IF((AND($L7<='LCS San Diego'!U$4,$M7>='LCS San Diego'!U$4)),"C",IF((AND($N7<='LCS San Diego'!U$4,$O7>='LCS San Diego'!U$4)),"CO",IF((AND($P7<='LCS San Diego'!U$4,$Q7>='LCS San Diego'!U$4)),"C",0)))))) -> 0 | V7: =IF((AND($E7<='LCS San Diego'!V$4,$F7>='LCS San Diego'!V$4)),"P/L",IF((AND($H7<='LCS San Diego'!V$4,$I7>='LCS San Diego'!V$4)),"XO",IF((AND($J7<='LCS San Diego'!V$4,$K7>='LCS San Diego'!V$4)),"3",IF((AND($L7<='LCS San Diego'!V$4,$M7>='LCS San Diego'!V$4)),"C",IF((AND($N7<='LCS San Diego'!V$4,$O7>='LCS San Diego'!V$4)),"CO",IF((AND($P7<='LCS San Diego'!V$4,$Q7>='LCS San Diego'!V$4)),"C",0)))))) -> 0 | W7: =IF((AND($E7<='LCS San Diego'!W$4,$F7>='LCS San Diego'!W$4)),"P/L",IF((AND($H7<='LCS San Diego'!W$4,$I7>='LCS San Diego'!W$4)),"XO",IF((AND($J7<='LCS San Diego'!W$4,$K7>='LCS San Diego'!W$4)),"3",IF((AND($L7<='LCS San Diego'!W$4,$M7>='LCS San Diego'!W$4)),"C",IF((AND($N7<='LCS San Diego'!W$4,$O7>='LCS San Diego'!W$4)),"CO",IF((AND($P7<='LCS San Diego'!W$4,$Q7>='LCS San Diego'!W$4)),"C",0)))))) -> CO | X7: =IF((AND($E7<='LCS San Diego'!X$4,$F7>='LCS San Diego'!X$4)),"P/L",IF((AND($H7<='LCS San Diego'!X$4,$I7>='LCS San Diego'!X$4)),"XO",IF((AND($J7<='LCS San Diego'!X$4,$K7>='LCS San Diego'!X$4)),"3",IF((AND($L7<='LCS San Diego'!X$4,$M7>='LCS San Diego'!X$4)),"C",IF((AND($N7<='LCS San Diego'!X$4,$O7>='LCS San Diego'!X$4)),"CO",IF((AND($P7<='LCS San Diego'!X$4,$Q7>='LCS San Diego'!X$4)),"C",0)))))) -> CO | Y7: =IF((AND($E7<='LCS San Diego'!Y$4,$F7>='LCS San Diego'!Y$4)),"P/L",IF((AND($H7<='LCS San Diego'!Y$4,$I7>='LCS San Diego'!Y$4)),"XO",IF((AND($J7<='LCS San Diego'!Y$4,$K7>='LCS San Diego'!Y$4)),"3",IF((AND($L7<='LCS San Diego'!Y$4,$M7>='LCS San Diego'!Y$4)),"C",IF((AND($N7<='LCS San Diego'!Y$4,$O7>='LCS San Diego'!Y$4)),"CO",IF((AND($P7<='LCS San Diego'!Y$4,$Q7>='LCS San Diego'!Y$4)),"C",0)))))) -> CO | ... CL7: =IF((AND($E7<='LCS San Diego'!CL$4,$F7>='LCS San Diego'!CL$4)),"P/L",IF((AND($H7<='LCS San Diego'!CL$4,$I7>='LCS San Diego'!CL$4)),"XO",IF((AND($J7<='LCS San Diego'!CL$4,$K7>='LCS San Diego'!CL$4)),"3",IF((AND($L7<='LCS San Diego'!CL$4,$M7>='LCS San Diego'!CL$4)),"C",IF((AND($N7<='LCS San Diego'!CL$4,$O7>='LCS San Diego'!CL$4)),"CO",IF((AND($P7<='LCS San Diego'!CL$4,$Q7>='LCS San Diego'!CL$4)),"C",0)))))) -> 0
A8: Bradford Jordan | B8: 9 | C8: 16 | D8: 1 | G8: =F8-E8 -> 0 | H8: 46138 | I8: =IF(H8="",0,DATE(YEAR(H8),MONTH(H8)+B8,DAY(H8))) -> 46413 | J8: =IF(I8="","",(DATE(YEAR(I8),MONTH(I8)+1,DAY(I8)))) -> 46444 | K8: =IF(J8="","",(DATE(YEAR(J8),MONTH(J8)+D8,DAY(J8)))) -> 46472 | L8: =IF(N8="","",DATE(YEAR(N8), MONTH(N8)-1,DAY(N8))) -> 46503 | M8: =IF(N8="","",DATE(YEAR(L8),MONTH(L8),DAY(L8))) -> 46503 | N8: =IF(K8="","",(DATE(YEAR(K8),MONTH(K8)+2,DAY(K8)))) -> 46533 | O8: =IF(N8="","",(DATE(YEAR(N8),MONTH(N8)+C8,DAY(N8)))) -> 47022 | P8: =IF(O8="","",DATE(YEAR(O8), MONTH(O8)+1,DAY(O8))) -> 47052 | Q8: =IF(O8="","",DATE(YEAR(P8),MONTH(P8),DAY(P8))) -> 47052 | R8: =IF((AND($E8<='LCS San Diego'!R$4,$F8>='LCS San Diego'!R$4)),"P/L",IF((AND($H8<='LCS San Diego'!R$4,$I8>='LCS San Diego'!R$4)),"XO",IF((AND($J8<='LCS San Diego'!R$4,$K8>='LCS San Diego'!R$4)),"3",IF((AND($L8<='LCS San Diego'!R$4,$M8>='LCS San Diego'!R$4)),"C",IF((AND($N8<='LCS San Diego'!R$4,$O8>='LCS San Diego'!R$4)),"CO",IF((AND($P8<='LCS San Diego'!R$4,$Q8>='LCS San Diego'!R$4)),"C",0)))))) -> 0 | S8: =IF((AND($E8<='LCS San Diego'!S$4,$F8>='LCS San Diego'!S$4)),"P/L",IF((AND($H8<='LCS San Diego'!S$4,$I8>='LCS San Diego'!S$4)),"XO",IF((AND($J8<='LCS San Diego'!S$4,$K8>='LCS San Diego'!S$4)),"3",IF((AND($L8<='LCS San Diego'!S$4,$M8>='LCS San Diego'!S$4)),"C",IF((AND($N8<='LCS San Diego'!S$4,$O8>='LCS San Diego'!S$4)),"CO",IF((AND($P8<='LCS San Diego'!S$4,$Q8>='LCS San Diego'!S$4)),"C",0)))))) -> 0 | T8: =IF((AND($E8<='LCS San Diego'!T$4,$F8>='LCS San Diego'!T$4)),"P/L",IF((AND($H8<='LCS San Diego'!T$4,$I8>='LCS San Diego'!T$4)),"XO",IF((AND($J8<='LCS San Diego'!T$4,$K8>='LCS San Diego'!T$4)),"3",IF((AND($L8<='LCS San Diego'!T$4,$M8>='LCS San Diego'!T$4)),"C",IF((AND($N8<='LCS San Diego'!T$4,$O8>='LCS San Diego'!T$4)),"CO",IF((AND($P8<='LCS San Diego'!T$4,$Q8>='LCS San Diego'!T$4)),"C",0)))))) -> 0 | U8: =IF((AND($E8<='LCS San Diego'!U$4,$F8>='LCS San Diego'!U$4)),"P/L",IF((AND($H8<='LCS San Diego'!U$4,$I8>='LCS San Diego'!U$4)),"XO",IF((AND($J8<='LCS San Diego'!U$4,$K8>='LCS San Diego'!U$4)),"3",IF((AND($L8<='LCS San Diego'!U$4,$M8>='LCS San Diego'!U$4)),"C",IF((AND($N8<='LCS San Diego'!U$4,$O8>='LCS San Diego'!U$4)),"CO",IF((AND($P8<='LCS San Diego'!U$4,$Q8>='LCS San Diego'!U$4)),"C",0)))))) -> XO | V8: =IF((AND($E8<='LCS San Diego'!V$4,$F8>='LCS San Diego'!V$4)),"P/L",IF((AND($H8<='LCS San Diego'!V$4,$I8>='LCS San Diego'!V$4)),"XO",IF((AND($J8<='LCS San Diego'!V$4,$K8>='LCS San Diego'!V$4)),"3",IF((AND($L8<='LCS San Diego'!V$4,$M8>='LCS San Diego'!V$4)),"C",IF((AND($N8<='LCS San Diego'!V$4,$O8>='LCS San Diego'!V$4)),"CO",IF((AND($P8<='LCS San Diego'!V$4,$Q8>='LCS San Diego'!V$4)),"C",0)))))) -> XO | W8: =IF((AND($E8<='LCS San Diego'!W$4,$F8>='LCS San Diego'!W$4)),"P/L",IF((AND($H8<='LCS San Diego'!W$4,$I8>='LCS San Diego'!W$4)),"XO",IF((AND($J8<='LCS San Diego'!W$4,$K8>='LCS San Diego'!W$4)),"3",IF((AND($L8<='LCS San Diego'!W$4,$M8>='LCS San Diego'!W$4)),"C",IF((AND($N8<='LCS San Diego'!W$4,$O8>='LCS San Diego'!W$4)),"CO",IF((AND($P8<='LCS San Diego'!W$4,$Q8>='LCS San Diego'!W$4)),"C",0)))))) -> XO | X8: =IF((AND($E8<='LCS San Diego'!X$4,$F8>='LCS San Diego'!X$4)),"P/L",IF((AND($H8<='LCS San Diego'!X$4,$I8>='LCS San Diego'!X$4)),"XO",IF((AND($J8<='LCS San Diego'!X$4,$K8>='LCS San Diego'!X$4)),"3",IF((AND($L8<='LCS San Diego'!X$4,$M8>='LCS San Diego'!X$4)),"C",IF((AND($N8<='LCS San Diego'!X$4,$O8>='LCS San Diego'!X$4)),"CO",IF((AND($P8<='LCS San Diego'!X$4,$Q8>='LCS San Diego'!X$4)),"C",0)))))) -> XO | Y8: =IF((AND($E8<='LCS San Diego'!Y$4,$F8>='LCS San Diego'!Y$4)),"P/L",IF((AND($H8<='LCS San Diego'!Y$4,$I8>='LCS San Diego'!Y$4)),"XO",IF((AND($J8<='LCS San Diego'!Y$4,$K8>='LCS San Diego'!Y$4)),"3",IF((AND($L8<='LCS San Diego'!Y$4,$M8>='LCS San Diego'!Y$4)),"C",IF((AND($N8<='LCS San Diego'!Y$4,$O8>='LCS San Diego'!Y$4)),"CO",IF((AND($P8<='LCS San Diego'!Y$4,$Q8>='LCS San Diego'!Y$4)),"C",0)))))) -> XO | ... CL8: =IF((AND($E8<='LCS San Diego'!CL$4,$F8>='LCS San Diego'!CL$4)),"P/L",IF((AND($H8<='LCS San Diego'!CL$4,$I8>='LCS San Diego'!CL$4)),"XO",IF((AND($J8<='LCS San Diego'!CL$4,$K8>='LCS San Diego'!CL$4)),"3",IF((AND($L8<='LCS San Diego'!CL$4,$M8>='LCS San Diego'!CL$4)),"C",IF((AND($N8<='LCS San Diego'!CL$4,$O8>='LCS San Diego'!CL$4)),"CO",IF((AND($P8<='LCS San Diego'!CL$4,$Q8>='LCS San Diego'!CL$4)),"C",0)))))) -> 0
A9: 26-2 | B9: 17 | C9: 16 | H9: 46414 | I9: =IF(H9="",0,DATE(YEAR(H9),MONTH(H9)+B9,DAY(H9))) -> 46931 | J9: =IF(I9="","",(DATE(YEAR(I9),MONTH(I9)+1,DAY(I9)))) -> 46961 | K9: =IF(J9="","",(DATE(YEAR(J9),MONTH(J9)+D9,DAY(J9)))) -> 46961 | L9: =IF(N9="","",DATE(YEAR(N9), MONTH(N9)-1,DAY(N9))) -> 46992 | M9: =IF(N9="","",DATE(YEAR(L9),MONTH(L9),DAY(L9))) -> 46992 | N9: =IF(K9="","",(DATE(YEAR(K9),MONTH(K9)+2,DAY(K9)))) -> 47023 | O9: =IF(N9="","",(DATE(YEAR(N9),MONTH(N9)+C9,DAY(N9)))) -> 47510 | P9: =IF(O9="","",DATE(YEAR(O9), MONTH(O9)+1,DAY(O9))) -> 47541 | Q9: =IF(O9="","",DATE(YEAR(P9),MONTH(P9),DAY(P9))) -> 47541
A10: TULSA (LCS 16) BLUE (CREW 215) - 41061 | R10: ='LCS San Diego'!$A$2-DAY('LCS San Diego'!$A$2)+1 -> 46054 | S10: =DATE(YEAR(R10),MONTH(R10)+1,DAY(R10)) -> 46082 | T10: =DATE(YEAR(S10),MONTH(S10)+1,DAY(S10)) -> 46113 | U10: =DATE(YEAR(T10),MONTH(T10)+1,DAY(T10)) -> 46143 | V10: =DATE(YEAR(U10),MONTH(U10)+1,DAY(U10)) -> 46174 | W10: =DATE(YEAR(V10),MONTH(V10)+1,DAY(V10)) -> 46204 | X10: =DATE(YEAR(W10),MONTH(W10)+1,DAY(W10)) -> 46235 | Y10: =DATE(YEAR(X10),MONTH(X10)+1,DAY(X10)) -> 46266 | Z10: =DATE(YEAR(Y10),MONTH(Y10)+1,DAY(Y10)) -> 46296 | ... CL10: =DATE(YEAR(CK10),MONTH(CK10)+1,DAY(CK10)) -> 48245
A11: Greenlees, Drew | B11: 15 | C11: 17 | D11: 1 | G11: =F11-E11 -> 0 | H11: 44136 | I11: 44764 | J11: =IF(I11="","",(DATE(YEAR(I11),MONTH(I11)+1,DAY(I11)))) -> 44795 | K11: 44795 | L11: =IF(N11="","",DATE(YEAR(N11), MONTH(N11)-1,DAY(N11))) -> 44826 | M11: =IF(N11="","",DATE(YEAR(L11),MONTH(L11),DAY(L11))) -> 44826 | N11: =IF(K11="","",(DATE(YEAR(K11),MONTH(K11)+2,DAY(K11)))) -> 44856 | O11: =IF(N11="","",(DATE(YEAR(N11),MONTH(N11)+C11,DAY(N11)))) -> 45373 | P11: 45375 | Q11: =IF(O11="","",DATE(YEAR(P11),MONTH(P11),DAY(P11))) -> 45375 | R11: =IF((AND($E11<='LCS San Diego'!R$4,$F11>='LCS San Diego'!R$4)),"P/L",IF((AND($H11<='LCS San Diego'!R$4,$I11>='LCS San Diego'!R$4)),"XO",IF((AND($J11<='LCS San Diego'!R$4,$K11>='LCS San Diego'!R$4)),"3",IF((AND($L11<='LCS San Diego'!R$4,$M11>='LCS San Diego'!R$4)),"C",IF((AND($N11<='LCS San Diego'!R$4,$O11>='LCS San Diego'!R$4)),"CO",IF((AND($P11<='LCS San Diego'!R$4,$Q11>='LCS San Diego'!R$4)),"C",0)))))) -> 0 | S11: =IF((AND($E11<='LCS San Diego'!S$4,$F11>='LCS San Diego'!S$4)),"P/L",IF((AND($H11<='LCS San Diego'!S$4,$I11>='LCS San Diego'!S$4)),"XO",IF((AND($J11<='LCS San Diego'!S$4,$K11>='LCS San Diego'!S$4)),"3",IF((AND($L11<='LCS San Diego'!S$4,$M11>='LCS San Diego'!S$4)),"C",IF((AND($N11<='LCS San Diego'!S$4,$O11>='LCS San Diego'!S$4)),"CO",IF((AND($P11<='LCS San Diego'!S$4,$Q11>='LCS San Diego'!S$4)),"C",0)))))) -> 0 | T11: =IF((AND($E11<='LCS San Diego'!T$4,$F11>='LCS San Diego'!T$4)),"P/L",IF((AND($H11<='LCS San Diego'!T$4,$I11>='LCS San Diego'!T$4)),"XO",IF((AND($J11<='LCS San Diego'!T$4,$K11>='LCS San Diego'!T$4)),"3",IF((AND($L11<='LCS San Diego'!T$4,$M11>='LCS San Diego'!T$4)),"C",IF((AND($N11<='LCS San Diego'!T$4,$O11>='LCS San Diego'!T$4)),"CO",IF((AND($P11<='LCS San Diego'!T$4,$Q11>='LCS San Diego'!T$4)),"C",0)))))) -> 0 | U11: =IF((AND($E11<='LCS San Diego'!U$4,$F11>='LCS San Diego'!U$4)),"P/L",IF((AND($H11<='LCS San Diego'!U$4,$I11>='LCS San Diego'!U$4)),"XO",IF((AND($J11<='LCS San Diego'!U$4,$K11>='LCS San Diego'!U$4)),"3",IF((AND($L11<='LCS San Diego'!U$4,$M11>='LCS San Diego'!U$4)),"C",IF((AND($N11<='LCS San Diego'!U$4,$O11>='LCS San Diego'!U$4)),"CO",IF((AND($P11<='LCS San Diego'!U$4,$Q11>='LCS San Diego'!U$4)),"C",0)))))) -> 0 | V11: =IF((AND($E11<='LCS San Diego'!V$4,$F11>='LCS San Diego'!V$4)),"P/L",IF((AND($H11<='LCS San Diego'!V$4,$I11>='LCS San Diego'!V$4)),"XO",IF((AND($J11<='LCS San Diego'!V$4,$K11>='LCS San Diego'!V$4)),"3",IF((AND($L11<='LCS San Diego'!V$4,$M11>='LCS San Diego'!V$4)),"C",IF((AND($N11<='LCS San Diego'!V$4,$O11>='LCS San Diego'!V$4)),"CO",IF((AND($P11<='LCS San Diego'!V$4,$Q11>='LCS San Diego'!V$4)),"C",0)))))) -> 0 | W11: =IF((AND($E11<='LCS San Diego'!W$4,$F11>='LCS San Diego'!W$4)),"P/L",IF((AND($H11<='LCS San Diego'!W$4,$I11>='LCS San Diego'!W$4)),"XO",IF((AND($J11<='LCS San Diego'!W$4,$K11>='LCS San Diego'!W$4)),"3",IF((AND($L11<='LCS San Diego'!W$4,$M11>='LCS San Diego'!W$4)),"C",IF((AND($N11<='LCS San Diego'!W$4,$O11>='LCS San Diego'!W$4)),"CO",IF((AND($P11<='LCS San Diego'!W$4,$Q11>='LCS San Diego'!W$4)),"C",0)))))) -> 0 | X11: =IF((AND($E11<='LCS San Diego'!X$4,$F11>='LCS San Diego'!X$4)),"P/L",IF((AND($H11<='LCS San Diego'!X$4,$I11>='LCS San Diego'!X$4)),"XO",IF((AND($J11<='LCS San Diego'!X$4,$K11>='LCS San Diego'!X$4)),"3",IF((AND($L11<='LCS San Diego'!X$4,$M11>='LCS San Diego'!X$4)),"C",IF((AND($N11<='LCS San Diego'!X$4,$O11>='LCS San Diego'!X$4)),"CO",IF((AND($P11<='LCS San Diego'!X$4,$Q11>='LCS San Diego'!X$4)),"C",0)))))) -> 0 | Y11: =IF((AND($E11<='LCS San Diego'!Y$4,$F11>='LCS San Diego'!Y$4)),"P/L",IF((AND($H11<='LCS San Diego'!Y$4,$I11>='LCS San Diego'!Y$4)),"XO",IF((AND($J11<='LCS San Diego'!Y$4,$K11>='LCS San Diego'!Y$4)),"3",IF((AND($L11<='LCS San Diego'!Y$4,$M11>='LCS San Diego'!Y$4)),"C",IF((AND($N11<='LCS San Diego'!Y$4,$O11>='LCS San Diego'!Y$4)),"CO",IF((AND($P11<='LCS San Diego'!Y$4,$Q11>='LCS San Diego'!Y$4)),"C",0)))))) -> 0 | ... CL11: =IF((AND($E11<='LCS San Diego'!CL$4,$F11>='LCS San Diego'!CL$4)),"P/L",IF((AND($H11<='LCS San Diego'!CL$4,$I11>='LCS San Diego'!CL$4)),"XO",IF((AND($J11<='LCS San Diego'!CL$4,$K11>='LCS San Diego'!CL$4)),"3",IF((AND($L11<='LCS San Diego'!CL$4,$M11>='LCS San Diego'!CL$4)),"C",IF((AND($N11<='LCS San Diego'!CL$4,$O11>='LCS San Diego'!CL$4)),"CO",IF((AND($P11<='LCS San Diego'!CL$4,$Q11>='LCS San Diego'!CL$4)),"C",0)))))) -> 0
A12: Moyer, Kyle (XO/CO) | B12: 15 | C12: 16 | D12: 1 | G12: =F12-E12 -> 0 | H12: 45346 | I12: =IF(H12="",0,DATE(YEAR(H12),MONTH(H12)+B12,DAY(H12))) -> 45801 | J12: =IF(I12="","",(DATE(YEAR(I12),MONTH(I12)+1,DAY(I12)))) -> 45832 | K12: =IF(J12="","",(DATE(YEAR(J12),MONTH(J12)+D12,DAY(J12)))) -> 45862 | L12: 45802 | M12: =IF(N12="","",DATE(YEAR(L12),MONTH(L12),DAY(L12))) -> 45802 | N12: =IF(K12="","",(DATE(YEAR(K12),MONTH(K12)+2,DAY(K12)))) -> 45924 | O12: =IF(N12="","",(DATE(YEAR(N12),MONTH(N12)+C12,DAY(N12)))) -> 46411 | P12: 46382 | Q12: =IF(O12="","",DATE(YEAR(P12),MONTH(P12),DAY(P12))) -> 46382 | R12: =IF((AND($E12<='LCS San Diego'!R$4,$F12>='LCS San Diego'!R$4)),"P/L",IF((AND($H12<='LCS San Diego'!R$4,$I12>='LCS San Diego'!R$4)),"XO",IF((AND($J12<='LCS San Diego'!R$4,$K12>='LCS San Diego'!R$4)),"3",IF((AND($L12<='LCS San Diego'!R$4,$M12>='LCS San Diego'!R$4)),"C",IF((AND($N12<='LCS San Diego'!R$4,$O12>='LCS San Diego'!R$4)),"CO",IF((AND($P12<='LCS San Diego'!R$4,$Q12>='LCS San Diego'!R$4)),"C",0)))))) -> CO | S12: =IF((AND($E12<='LCS San Diego'!S$4,$F12>='LCS San Diego'!S$4)),"P/L",IF((AND($H12<='LCS San Diego'!S$4,$I12>='LCS San Diego'!S$4)),"XO",IF((AND($J12<='LCS San Diego'!S$4,$K12>='LCS San Diego'!S$4)),"3",IF((AND($L12<='LCS San Diego'!S$4,$M12>='LCS San Diego'!S$4)),"C",IF((AND($N12<='LCS San Diego'!S$4,$O12>='LCS San Diego'!S$4)),"CO",IF((AND($P12<='LCS San Diego'!S$4,$Q12>='LCS San Diego'!S$4)),"C",0)))))) -> CO | T12: =IF((AND($E12<='LCS San Diego'!T$4,$F12>='LCS San Diego'!T$4)),"P/L",IF((AND($H12<='LCS San Diego'!T$4,$I12>='LCS San Diego'!T$4)),"XO",IF((AND($J12<='LCS San Diego'!T$4,$K12>='LCS San Diego'!T$4)),"3",IF((AND($L12<='LCS San Diego'!T$4,$M12>='LCS San Diego'!T$4)),"C",IF((AND($N12<='LCS San Diego'!T$4,$O12>='LCS San Diego'!T$4)),"CO",IF((AND($P12<='LCS San Diego'!T$4,$Q12>='LCS San Diego'!T$4)),"C",0)))))) -> CO | U12: =IF((AND($E12<='LCS San Diego'!U$4,$F12>='LCS San Diego'!U$4)),"P/L",IF((AND($H12<='LCS San Diego'!U$4,$I12>='LCS San Diego'!U$4)),"XO",IF((AND($J12<='LCS San Diego'!U$4,$K12>='LCS San Diego'!U$4)),"3",IF((AND($L12<='LCS San Diego'!U$4,$M12>='LCS San Diego'!U$4)),"C",IF((AND($N12<='LCS San Diego'!U$4,$O12>='LCS San Diego'!U$4)),"CO",IF((AND($P12<='LCS San Diego'!U$4,$Q12>='LCS San Diego'!U$4)),"C",0)))))) -> CO | V12: =IF((AND($E12<='LCS San Diego'!V$4,$F12>='LCS San Diego'!V$4)),"P/L",IF((AND($H12<='LCS San Diego'!V$4,$I12>='LCS San Diego'!V$4)),"XO",IF((AND($J12<='LCS San Diego'!V$4,$K12>='LCS San Diego'!V$4)),"3",IF((AND($L12<='LCS San Diego'!V$4,$M12>='LCS San Diego'!V$4)),"C",IF((AND($N12<='LCS San Diego'!V$4,$O12>='LCS San Diego'!V$4)),"CO",IF((AND($P12<='LCS San Diego'!V$4,$Q12>='LCS San Diego'!V$4)),"C",0)))))) -> CO | W12: =IF((AND($E12<='LCS San Diego'!W$4,$F12>='LCS San Diego'!W$4)),"P/L",IF((AND($H12<='LCS San Diego'!W$4,$I12>='LCS San Diego'!W$4)),"XO",IF((AND($J12<='LCS San Diego'!W$4,$K12>='LCS San Diego'!W$4)),"3",IF((AND($L12<='LCS San Diego'!W$4,$M12>='LCS San Diego'!W$4)),"C",IF((AND($N12<='LCS San Diego'!W$4,$O12>='LCS San Diego'!W$4)),"CO",IF((AND($P12<='LCS San Diego'!W$4,$Q12>='LCS San Diego'!W$4)),"C",0)))))) -> CO | X12: =IF((AND($E12<='LCS San Diego'!X$4,$F12>='LCS San Diego'!X$4)),"P/L",IF((AND($H12<='LCS San Diego'!X$4,$I12>='LCS San Diego'!X$4)),"XO",IF((AND($J12<='LCS San Diego'!X$4,$K12>='LCS San Diego'!X$4)),"3",IF((AND($L12<='LCS San Diego'!X$4,$M12>='LCS San Diego'!X$4)),"C",IF((AND($N12<='LCS San Diego'!X$4,$O12>='LCS San Diego'!X$4)),"CO",IF((AND($P12<='LCS San Diego'!X$4,$Q12>='LCS San Diego'!X$4)),"C",0)))))) -> CO | Y12: =IF((AND($E12<='LCS San Diego'!Y$4,$F12>='LCS San Diego'!Y$4)),"P/L",IF((AND($H12<='LCS San Diego'!Y$4,$I12>='LCS San Diego'!Y$4)),"XO",IF((AND($J12<='LCS San Diego'!Y$4,$K12>='LCS San Diego'!Y$4)),"3",IF((AND($L12<='LCS San Diego'!Y$4,$M12>='LCS San Diego'!Y$4)),"C",IF((AND($N12<='LCS San Diego'!Y$4,$O12>='LCS San Diego'!Y$4)),"CO",IF((AND($P12<='LCS San Diego'!Y$4,$Q12>='LCS San Diego'!Y$4)),"C",0)))))) -> CO | ... CL12: =IF((AND($E12<='LCS San Diego'!CL$4,$F12>='LCS San Diego'!CL$4)),"P/L",IF((AND($H12<='LCS San Diego'!CL$4,$I12>='LCS San Diego'!CL$4)),"XO",IF((AND($J12<='LCS San Diego'!CL$4,$K12>='LCS San Diego'!CL$4)),"3",IF((AND($L12<='LCS San Diego'!CL$4,$M12>='LCS San Diego'!CL$4)),"C",IF((AND($N12<='LCS San Diego'!CL$4,$O12>='LCS San Diego'!CL$4)),"CO",IF((AND($P12<='LCS San Diego'!CL$4,$Q12>='LCS San Diego'!CL$4)),"C",0)))))) -> 0
A13: Zarow, Zachary (24-3) | B13: 18 | C13: 16 | D13: 1 | G13: =F13-E13 -> 0 | H13: 45894 | I13: =IF(H13="",0,DATE(YEAR(H13),MONTH(H13)+B13,DAY(H13))) -> 46443 | J13: =IF(I13="","",(DATE(YEAR(I13),MONTH(I13)+1,DAY(I13)))) -> 46471 | K13: =IF(J13="","",(DATE(YEAR(J13),MONTH(J13)+D13,DAY(J13)))) -> 46502 | L13: =IF(N13="","",DATE(YEAR(N13), MONTH(N13)-1,DAY(N13))) -> 46532 | M13: =IF(N13="","",DATE(YEAR(L13),MONTH(L13),DAY(L13))) -> 46532 | N13: =IF(K13="","",(DATE(YEAR(K13),MONTH(K13)+2,DAY(K13)))) -> 46563 | O13: =IF(N13="","",(DATE(YEAR(N13),MONTH(N13)+C13,DAY(N13)))) -> 47051 | P13: =IF(O13="","",DATE(YEAR(O13), MONTH(O13)+1,DAY(O13))) -> 47082 | Q13: =IF(O13="","",DATE(YEAR(P13),MONTH(P13),DAY(P13))) -> 47082 | R13: =IF((AND($E13<='LCS San Diego'!R$4,$F13>='LCS San Diego'!R$4)),"P/L",IF((AND($H13<='LCS San Diego'!R$4,$I13>='LCS San Diego'!R$4)),"XO",IF((AND($J13<='LCS San Diego'!R$4,$K13>='LCS San Diego'!R$4)),"3",IF((AND($L13<='LCS San Diego'!R$4,$M13>='LCS San Diego'!R$4)),"C",IF((AND($N13<='LCS San Diego'!R$4,$O13>='LCS San Diego'!R$4)),"CO",IF((AND($P13<='LCS San Diego'!R$4,$Q13>='LCS San Diego'!R$4)),"C",0)))))) -> XO | S13: =IF((AND($E13<='LCS San Diego'!S$4,$F13>='LCS San Diego'!S$4)),"P/L",IF((AND($H13<='LCS San Diego'!S$4,$I13>='LCS San Diego'!S$4)),"XO",IF((AND($J13<='LCS San Diego'!S$4,$K13>='LCS San Diego'!S$4)),"3",IF((AND($L13<='LCS San Diego'!S$4,$M13>='LCS San Diego'!S$4)),"C",IF((AND($N13<='LCS San Diego'!S$4,$O13>='LCS San Diego'!S$4)),"CO",IF((AND($P13<='LCS San Diego'!S$4,$Q13>='LCS San Diego'!S$4)),"C",0)))))) -> XO | T13: =IF((AND($E13<='LCS San Diego'!T$4,$F13>='LCS San Diego'!T$4)),"P/L",IF((AND($H13<='LCS San Diego'!T$4,$I13>='LCS San Diego'!T$4)),"XO",IF((AND($J13<='LCS San Diego'!T$4,$K13>='LCS San Diego'!T$4)),"3",IF((AND($L13<='LCS San Diego'!T$4,$M13>='LCS San Diego'!T$4)),"C",IF((AND($N13<='LCS San Diego'!T$4,$O13>='LCS San Diego'!T$4)),"CO",IF((AND($P13<='LCS San Diego'!T$4,$Q13>='LCS San Diego'!T$4)),"C",0)))))) -> XO | U13: =IF((AND($E13<='LCS San Diego'!U$4,$F13>='LCS San Diego'!U$4)),"P/L",IF((AND($H13<='LCS San Diego'!U$4,$I13>='LCS San Diego'!U$4)),"XO",IF((AND($J13<='LCS San Diego'!U$4,$K13>='LCS San Diego'!U$4)),"3",IF((AND($L13<='LCS San Diego'!U$4,$M13>='LCS San Diego'!U$4)),"C",IF((AND($N13<='LCS San Diego'!U$4,$O13>='LCS San Diego'!U$4)),"CO",IF((AND($P13<='LCS San Diego'!U$4,$Q13>='LCS San Diego'!U$4)),"C",0)))))) -> XO | V13: =IF((AND($E13<='LCS San Diego'!V$4,$F13>='LCS San Diego'!V$4)),"P/L",IF((AND($H13<='LCS San Diego'!V$4,$I13>='LCS San Diego'!V$4)),"XO",IF((AND($J13<='LCS San Diego'!V$4,$K13>='LCS San Diego'!V$4)),"3",IF((AND($L13<='LCS San Diego'!V$4,$M13>='LCS San Diego'!V$4)),"C",IF((AND($N13<='LCS San Diego'!V$4,$O13>='LCS San Diego'!V$4)),"CO",IF((AND($P13<='LCS San Diego'!V$4,$Q13>='LCS San Diego'!V$4)),"C",0)))))) -> XO | W13: =IF((AND($E13<='LCS San Diego'!W$4,$F13>='LCS San Diego'!W$4)),"P/L",IF((AND($H13<='LCS San Diego'!W$4,$I13>='LCS San Diego'!W$4)),"XO",IF((AND($J13<='LCS San Diego'!W$4,$K13>='LCS San Diego'!W$4)),"3",IF((AND($L13<='LCS San Diego'!W$4,$M13>='LCS San Diego'!W$4)),"C",IF((AND($N13<='LCS San Diego'!W$4,$O13>='LCS San Diego'!W$4)),"CO",IF((AND($P13<='LCS San Diego'!W$4,$Q13>='LCS San Diego'!W$4)),"C",0)))))) -> XO | X13: =IF((AND($E13<='LCS San Diego'!X$4,$F13>='LCS San Diego'!X$4)),"P/L",IF((AND($H13<='LCS San Diego'!X$4,$I13>='LCS San Diego'!X$4)),"XO",IF((AND($J13<='LCS San Diego'!X$4,$K13>='LCS San Diego'!X$4)),"3",IF((AND($L13<='LCS San Diego'!X$4,$M13>='LCS San Diego'!X$4)),"C",IF((AND($N13<='LCS San Diego'!X$4,$O13>='LCS San Diego'!X$4)),"CO",IF((AND($P13<='LCS San Diego'!X$4,$Q13>='LCS San Diego'!X$4)),"C",0)))))) -> XO | Y13: =IF((AND($E13<='LCS San Diego'!Y$4,$F13>='LCS San Diego'!Y$4)),"P/L",IF((AND($H13<='LCS San Diego'!Y$4,$I13>='LCS San Diego'!Y$4)),"XO",IF((AND($J13<='LCS San Diego'!Y$4,$K13>='LCS San Diego'!Y$4)),"3",IF((AND($L13<='LCS San Diego'!Y$4,$M13>='LCS San Diego'!Y$4)),"C",IF((AND($N13<='LCS San Diego'!Y$4,$O13>='LCS San Diego'!Y$4)),"CO",IF((AND($P13<='LCS San Diego'!Y$4,$Q13>='LCS San Diego'!Y$4)),"C",0)))))) -> XO | ... CL13: =IF((AND($E13<='LCS San Diego'!CL$4,$F13>='LCS San Diego'!CL$4)),"P/L",IF((AND($H13<='LCS San Diego'!CL$4,$I13>='LCS San Diego'!CL$4)),"XO",IF((AND($J13<='LCS San Diego'!CL$4,$K13>='LCS San Diego'!CL$4)),"3",IF((AND($L13<='LCS San Diego'!CL$4,$M13>='LCS San Diego'!CL$4)),"C",IF((AND($N13<='LCS San Diego'!CL$4,$O13>='LCS San Diego'!CL$4)),"CO",IF((AND($P13<='LCS San Diego'!CL$4,$Q13>='LCS San Diego'!CL$4)),"C",0)))))) -> 0
A14: Benko, Ryan (24-4) (EDA 2505) (XO/CO) | B14: 15 | C14: 16 | D14: 1 | H14: 45803 | I14: =IF(H14="",0,DATE(YEAR(H14),MONTH(H14)+B14,DAY(H14))) -> 46260 | J14: =IF(I14="","",(DATE(YEAR(I14),MONTH(I14)+1,DAY(I14)))) -> 46291 | K14: =IF(J14="","",(DATE(YEAR(J14),MONTH(J14)+D14,DAY(J14)))) -> 46321 | L14: =IF(N14="","",DATE(YEAR(N14), MONTH(N14)-1,DAY(N14))) -> 46352 | M14: =IF(N14="","",DATE(YEAR(L14),MONTH(L14),DAY(L14))) -> 46352 | N14: =IF(K14="","",(DATE(YEAR(K14),MONTH(K14)+2,DAY(K14)))) -> 46382 | O14: =IF(N14="","",(DATE(YEAR(N14),MONTH(N14)+C14,DAY(N14)))) -> 46869 | P14: =IF(O14="","",DATE(YEAR(O14), MONTH(O14)+1,DAY(O14))) -> 46899 | Q14: =IF(O14="","",DATE(YEAR(P14),MONTH(P14),DAY(P14))) -> 46899
A15: Bradford, Jordan (24-2) | B15: 17 | C15: 16 | D15: 1 | G15: =F15-E15 -> 0 | H15: 45894 | I15: =IF(H15="",0,DATE(YEAR(H15),MONTH(H15)+B15,DAY(H15))) -> 46412 | J15: =IF(I15="","",(DATE(YEAR(I15),MONTH(I15)+1,DAY(I15)))) -> 46443 | K15: =IF(J15="","",(DATE(YEAR(J15),MONTH(J15)+D15,DAY(J15)))) -> 46471 | L15: 46748 | M15: =IF(N15="","",DATE(YEAR(L15),MONTH(L15),DAY(L15))) -> 46748 | N15: =IF(K15="","",(DATE(YEAR(K15),MONTH(K15)+2,DAY(K15)))) -> 46532 | O15: =IF(N15="","",(DATE(YEAR(N15),MONTH(N15)+C15,DAY(N15)))) -> 47021 | P15: =IF(O15="","",DATE(YEAR(O15), MONTH(O15)+1,DAY(O15))) -> 47051 | Q15: =IF(O15="","",DATE(YEAR(P15),MONTH(P15),DAY(P15))) -> 47051
A16: 26-2 | B16: 17 | C16: 16 | D16: 1 | H16: 46388 | I16: =IF(H16="",0,DATE(YEAR(H16),MONTH(H16)+B16,DAY(H16))) -> 46905 | J16: =IF(I16="","",(DATE(YEAR(I16),MONTH(I16)+1,DAY(I16)))) -> 46935 | K16: =IF(J16="","",(DATE(YEAR(J16),MONTH(J16)+D16,DAY(J16)))) -> 46966 | L16: =IF(N16="","",DATE(YEAR(N16), MONTH(N16)-1,DAY(N16))) -> 46997 | M16: =IF(N16="","",DATE(YEAR(L16),MONTH(L16),DAY(L16))) -> 46997 | N16: =IF(K16="","",(DATE(YEAR(K16),MONTH(K16)+2,DAY(K16)))) -> 47027 | O16: =IF(N16="","",(DATE(YEAR(N16),MONTH(N16)+C16,DAY(N16)))) -> 47515 | P16: =IF(O16="","",DATE(YEAR(O16), MONTH(O16)+1,DAY(O16))) -> 47543 | Q16: =IF(O16="","",DATE(YEAR(P16),MONTH(P16),DAY(P16))) -> 47543
A17: TULSA (LCS 16) GOLD (CREW 217) - 41069 | R17: ='LCS San Diego'!$A$2-DAY('LCS San Diego'!$A$2)+1 -> 46054 | S17: =DATE(YEAR(R17),MONTH(R17)+1,DAY(R17)) -> 46082 | T17: =DATE(YEAR(S17),MONTH(S17)+1,DAY(S17)) -> 46113 | U17: =DATE(YEAR(T17),MONTH(T17)+1,DAY(T17)) -> 46143 | V17: =DATE(YEAR(U17),MONTH(U17)+1,DAY(U17)) -> 46174 | W17: =DATE(YEAR(V17),MONTH(V17)+1,DAY(V17)) -> 46204 | X17: =DATE(YEAR(W17),MONTH(W17)+1,DAY(W17)) -> 46235 | Y17: =DATE(YEAR(X17),MONTH(X17)+1,DAY(X17)) -> 46266 | Z17: =DATE(YEAR(Y17),MONTH(Y17)+1,DAY(Y17)) -> 46296 | ... CL17: =DATE(YEAR(CK17),MONTH(CK17)+1,DAY(CK17)) -> 48245
A18: Wanier, Blake (XO/CO) | B18: 17 | C18: 17 | D18: 1 | G18: =F18-E18 -> 0 | H18: 45374 | I18: =IF(H18="",0,DATE(YEAR(H18),MONTH(H18)+B18,DAY(H18))) -> 45892 | J18: =IF(I18="","",(DATE(YEAR(I18),MONTH(I18)+1,DAY(I18)))) -> 45923 | K18: =IF(J18="","",(DATE(YEAR(J18),MONTH(J18)+D18,DAY(J18)))) -> 45953 | L18: =IF(N18="","",DATE(YEAR(N18), MONTH(N18)-1,DAY(N18))) -> 45984 | M18: =IF(N18="","",DATE(YEAR(L18),MONTH(L18),DAY(L18))) -> 45984 | N18: =IF(K18="","",(DATE(YEAR(K18),MONTH(K18)+2,DAY(K18)))) -> 46014 | O18: =IF(N18="","",(DATE(YEAR(N18),MONTH(N18)+C18,DAY(N18)))) -> 46530 | P18: =IF(O18="","",DATE(YEAR(O18), MONTH(O18)+1,DAY(O18))) -> 46561 | Q18: =IF(O18="","",DATE(YEAR(P18),MONTH(P18),DAY(P18))) -> 46561 | R18: =IF((AND($E18<='LCS San Diego'!R$4,$F18>='LCS San Diego'!R$4)),"P/L",IF((AND($H18<='LCS San Diego'!R$4,$I18>='LCS San Diego'!R$4)),"XO",IF((AND($J18<='LCS San Diego'!R$4,$K18>='LCS San Diego'!R$4)),"3",IF((AND($L18<='LCS San Diego'!R$4,$M18>='LCS San Diego'!R$4)),"C",IF((AND($N18<='LCS San Diego'!R$4,$O18>='LCS San Diego'!R$4)),"CO",IF((AND($P18<='LCS San Diego'!R$4,$Q18>='LCS San Diego'!R$4)),"C",0)))))) -> CO | S18: =IF((AND($E18<='LCS San Diego'!S$4,$F18>='LCS San Diego'!S$4)),"P/L",IF((AND($H18<='LCS San Diego'!S$4,$I18>='LCS San Diego'!S$4)),"XO",IF((AND($J18<='LCS San Diego'!S$4,$K18>='LCS San Diego'!S$4)),"3",IF((AND($L18<='LCS San Diego'!S$4,$M18>='LCS San Diego'!S$4)),"C",IF((AND($N18<='LCS San Diego'!S$4,$O18>='LCS San Diego'!S$4)),"CO",IF((AND($P18<='LCS San Diego'!S$4,$Q18>='LCS San Diego'!S$4)),"C",0)))))) -> CO | T18: =IF((AND($E18<='LCS San Diego'!T$4,$F18>='LCS San Diego'!T$4)),"P/L",IF((AND($H18<='LCS San Diego'!T$4,$I18>='LCS San Diego'!T$4)),"XO",IF((AND($J18<='LCS San Diego'!T$4,$K18>='LCS San Diego'!T$4)),"3",IF((AND($L18<='LCS San Diego'!T$4,$M18>='LCS San Diego'!T$4)),"C",IF((AND($N18<='LCS San Diego'!T$4,$O18>='LCS San Diego'!T$4)),"CO",IF((AND($P18<='LCS San Diego'!T$4,$Q18>='LCS San Diego'!T$4)),"C",0)))))) -> CO | U18: =IF((AND($E18<='LCS San Diego'!U$4,$F18>='LCS San Diego'!U$4)),"P/L",IF((AND($H18<='LCS San Diego'!U$4,$I18>='LCS San Diego'!U$4)),"XO",IF((AND($J18<='LCS San Diego'!U$4,$K18>='LCS San Diego'!U$4)),"3",IF((AND($L18<='LCS San Diego'!U$4,$M18>='LCS San Diego'!U$4)),"C",IF((AND($N18<='LCS San Diego'!U$4,$O18>='LCS San Diego'!U$4)),"CO",IF((AND($P18<='LCS San Diego'!U$4,$Q18>='LCS San Diego'!U$4)),"C",0)))))) -> CO | V18: =IF((AND($E18<='LCS San Diego'!V$4,$F18>='LCS San Diego'!V$4)),"P/L",IF((AND($H18<='LCS San Diego'!V$4,$I18>='LCS San Diego'!V$4)),"XO",IF((AND($J18<='LCS San Diego'!V$4,$K18>='LCS San Diego'!V$4)),"3",IF((AND($L18<='LCS San Diego'!V$4,$M18>='LCS San Diego'!V$4)),"C",IF((AND($N18<='LCS San Diego'!V$4,$O18>='LCS San Diego'!V$4)),"CO",IF((AND($P18<='LCS San Diego'!V$4,$Q18>='LCS San Diego'!V$4)),"C",0)))))) -> CO | W18: =IF((AND($E18<='LCS San Diego'!W$4,$F18>='LCS San Diego'!W$4)),"P/L",IF((AND($H18<='LCS San Diego'!W$4,$I18>='LCS San Diego'!W$4)),"XO",IF((AND($J18<='LCS San Diego'!W$4,$K18>='LCS San Diego'!W$4)),"3",IF((AND($L18<='LCS San Diego'!W$4,$M18>='LCS San Diego'!W$4)),"C",IF((AND($N18<='LCS San Diego'!W$4,$O18>='LCS San Diego'!W$4)),"CO",IF((AND($P18<='LCS San Diego'!W$4,$Q18>='LCS San Diego'!W$4)),"C",0)))))) -> CO | X18: =IF((AND($E18<='LCS San Diego'!X$4,$F18>='LCS San Diego'!X$4)),"P/L",IF((AND($H18<='LCS San Diego'!X$4,$I18>='LCS San Diego'!X$4)),"XO",IF((AND($J18<='LCS San Diego'!X$4,$K18>='LCS San Diego'!X$4)),"3",IF((AND($L18<='LCS San Diego'!X$4,$M18>='LCS San Diego'!X$4)),"C",IF((AND($N18<='LCS San Diego'!X$4,$O18>='LCS San Diego'!X$4)),"CO",IF((AND($P18<='LCS San Diego'!X$4,$Q18>='LCS San Diego'!X$4)),"C",0)))))) -> CO | Y18: =IF((AND($E18<='LCS San Diego'!Y$4,$F18>='LCS San Diego'!Y$4)),"P/L",IF((AND($H18<='LCS San Diego'!Y$4,$I18>='LCS San Diego'!Y$4)),"XO",IF((AND($J18<='LCS San Diego'!Y$4,$K18>='LCS San Diego'!Y$4)),"3",IF((AND($L18<='LCS San Diego'!Y$4,$M18>='LCS San Diego'!Y$4)),"C",IF((AND($N18<='LCS San Diego'!Y$4,$O18>='LCS San Diego'!Y$4)),"CO",IF((AND($P18<='LCS San Diego'!Y$4,$Q18>='LCS San Diego'!Y$4)),"C",0)))))) -> CO | ... CL18: =IF((AND($E18<='LCS San Diego'!CL$4,$F18>='LCS San Diego'!CL$4)),"P/L",IF((AND($H18<='LCS San Diego'!CL$4,$I18>='LCS San Diego'!CL$4)),"XO",IF((AND($J18<='LCS San Diego'!CL$4,$K18>='LCS San Diego'!CL$4)),"3",IF((AND($L18<='LCS San Diego'!CL$4,$M18>='LCS San Diego'!CL$4)),"C",IF((AND($N18<='LCS San Diego'!CL$4,$O18>='LCS San Diego'!CL$4)),"CO",IF((AND($P18<='LCS San Diego'!CL$4,$Q18>='LCS San Diego'!CL$4)),"C",0)))))) -> 0
A19: Bradford, Jordan (24-2) | B19: 17 | C19: 16 | D19: 1 | G19: =F19-E19 -> 0 | H19: 45894 | I19: =IF(H19="",0,DATE(YEAR(H19),MONTH(H19)+B19,DAY(H19))) -> 46412 | J19: =IF(I19="","",(DATE(YEAR(I19),MONTH(I19)+1,DAY(I19)))) -> 46443 | K19: =IF(J19="","",(DATE(YEAR(J19),MONTH(J19)+D19,DAY(J19)))) -> 46471 | L19: =IF(N19="","",DATE(YEAR(N19), MONTH(N19)-1,DAY(N19))) -> 46502 | M19: =IF(N19="","",DATE(YEAR(L19),MONTH(L19),DAY(L19))) -> 46502 | N19: =IF(K19="","",(DATE(YEAR(K19),MONTH(K19)+2,DAY(K19)))) -> 46532 | O19: =IF(N19="","",(DATE(YEAR(N19),MONTH(N19)+C19,DAY(N19)))) -> 47021 | P19: =IF(O19="","",DATE(YEAR(O19), MONTH(O19)+1,DAY(O19))) -> 47051 | Q19: =IF(O19="","",DATE(YEAR(P19),MONTH(P19),DAY(P19))) -> 47051 | R19: =IF((AND($E19<='LCS San Diego'!R$4,$F19>='LCS San Diego'!R$4)),"P/L",IF((AND($H19<='LCS San Diego'!R$4,$I19>='LCS San Diego'!R$4)),"XO",IF((AND($J19<='LCS San Diego'!R$4,$K19>='LCS San Diego'!R$4)),"3",IF((AND($L19<='LCS San Diego'!R$4,$M19>='LCS San Diego'!R$4)),"C",IF((AND($N19<='LCS San Diego'!R$4,$O19>='LCS San Diego'!R$4)),"CO",IF((AND($P19<='LCS San Diego'!R$4,$Q19>='LCS San Diego'!R$4)),"C",0)))))) -> XO | S19: =IF((AND($E19<='LCS San Diego'!S$4,$F19>='LCS San Diego'!S$4)),"P/L",IF((AND($H19<='LCS San Diego'!S$4,$I19>='LCS San Diego'!S$4)),"XO",IF((AND($J19<='LCS San Diego'!S$4,$K19>='LCS San Diego'!S$4)),"3",IF((AND($L19<='LCS San Diego'!S$4,$M19>='LCS San Diego'!S$4)),"C",IF((AND($N19<='LCS San Diego'!S$4,$O19>='LCS San Diego'!S$4)),"CO",IF((AND($P19<='LCS San Diego'!S$4,$Q19>='LCS San Diego'!S$4)),"C",0)))))) -> XO | T19: =IF((AND($E19<='LCS San Diego'!T$4,$F19>='LCS San Diego'!T$4)),"P/L",IF((AND($H19<='LCS San Diego'!T$4,$I19>='LCS San Diego'!T$4)),"XO",IF((AND($J19<='LCS San Diego'!T$4,$K19>='LCS San Diego'!T$4)),"3",IF((AND($L19<='LCS San Diego'!T$4,$M19>='LCS San Diego'!T$4)),"C",IF((AND($N19<='LCS San Diego'!T$4,$O19>='LCS San Diego'!T$4)),"CO",IF((AND($P19<='LCS San Diego'!T$4,$Q19>='LCS San Diego'!T$4)),"C",0)))))) -> XO | U19: =IF((AND($E19<='LCS San Diego'!U$4,$F19>='LCS San Diego'!U$4)),"P/L",IF((AND($H19<='LCS San Diego'!U$4,$I19>='LCS San Diego'!U$4)),"XO",IF((AND($J19<='LCS San Diego'!U$4,$K19>='LCS San Diego'!U$4)),"3",IF((AND($L19<='LCS San Diego'!U$4,$M19>='LCS San Diego'!U$4)),"C",IF((AND($N19<='LCS San Diego'!U$4,$O19>='LCS San Diego'!U$4)),"CO",IF((AND($P19<='LCS San Diego'!U$4,$Q19>='LCS San Diego'!U$4)),"C",0)))))) -> XO | V19: =IF((AND($E19<='LCS San Diego'!V$4,$F19>='LCS San Diego'!V$4)),"P/L",IF((AND($H19<='LCS San Diego'!V$4,$I19>='LCS San Diego'!V$4)),"XO",IF((AND($J19<='LCS San Diego'!V$4,$K19>='LCS San Diego'!V$4)),"3",IF((AND($L19<='LCS San Diego'!V$4,$M19>='LCS San Diego'!V$4)),"C",IF((AND($N19<='LCS San Diego'!V$4,$O19>='LCS San Diego'!V$4)),"CO",IF((AND($P19<='LCS San Diego'!V$4,$Q19>='LCS San Diego'!V$4)),"C",0)))))) -> XO | W19: =IF((AND($E19<='LCS San Diego'!W$4,$F19>='LCS San Diego'!W$4)),"P/L",IF((AND($H19<='LCS San Diego'!W$4,$I19>='LCS San Diego'!W$4)),"XO",IF((AND($J19<='LCS San Diego'!W$4,$K19>='LCS San Diego'!W$4)),"3",IF((AND($L19<='LCS San Diego'!W$4,$M19>='LCS San Diego'!W$4)),"C",IF((AND($N19<='LCS San Diego'!W$4,$O19>='LCS San Diego'!W$4)),"CO",IF((AND($P19<='LCS San Diego'!W$4,$Q19>='LCS San Diego'!W$4)),"C",0)))))) -> XO | X19: =IF((AND($E19<='LCS San Diego'!X$4,$F19>='LCS San Diego'!X$4)),"P/L",IF((AND($H19<='LCS San Diego'!X$4,$I19>='LCS San Diego'!X$4)),"XO",IF((AND($J19<='LCS San Diego'!X$4,$K19>='LCS San Diego'!X$4)),"3",IF((AND($L19<='LCS San Diego'!X$4,$M19>='LCS San Diego'!X$4)),"C",IF((AND($N19<='LCS San Diego'!X$4,$O19>='LCS San Diego'!X$4)),"CO",IF((AND($P19<='LCS San Diego'!X$4,$Q19>='LCS San Diego'!X$4)),"C",0)))))) -> XO | Y19: =IF((AND($E19<='LCS San Diego'!Y$4,$F19>='LCS San Diego'!Y$4)),"P/L",IF((AND($H19<='LCS San Diego'!Y$4,$I19>='LCS San Diego'!Y$4)),"XO",IF((AND($J19<='LCS San Diego'!Y$4,$K19>='LCS San Diego'!Y$4)),"3",IF((AND($L19<='LCS San Diego'!Y$4,$M19>='LCS San Diego'!Y$4)),"C",IF((AND($N19<='LCS San Diego'!Y$4,$O19>='LCS San Diego'!Y$4)),"CO",IF((AND($P19<='LCS San Diego'!Y$4,$Q19>='LCS San Diego'!Y$4)),"C",0)))))) -> XO | ... CL19: =IF((AND($E19<='LCS San Diego'!CL$4,$F19>='LCS San Diego'!CL$4)),"P/L",IF((AND($H19<='LCS San Diego'!CL$4,$I19>='LCS San Diego'!CL$4)),"XO",IF((AND($J19<='LCS San Diego'!CL$4,$K19>='LCS San Diego'!CL$4)),"3",IF((AND($L19<='LCS San Diego'!CL$4,$M19>='LCS San Diego'!CL$4)),"C",IF((AND($N19<='LCS San Diego'!CL$4,$O19>='LCS San Diego'!CL$4)),"CO",IF((AND($P19<='LCS San Diego'!CL$4,$Q19>='LCS San Diego'!CL$4)),"C",0)))))) -> 0
A20: 26-1 Don't need | B20: 17 | C20: 16 | D20: 1 | G20: =F20-E20 -> 0 | H20: 46388 | I20: =IF(H20="",0,DATE(YEAR(H20),MONTH(H20)+B20,DAY(H20))) -> 46905 | J20: =IF(I20="","",(DATE(YEAR(I20),MONTH(I20)+1,DAY(I20)))) -> 46935 | K20: =IF(J20="","",(DATE(YEAR(J20),MONTH(J20)+D20,DAY(J20)))) -> 46966 | L20: =IF(N20="","",DATE(YEAR(N20), MONTH(N20)-1,DAY(N20))) -> 46997 | M20: =IF(N20="","",DATE(YEAR(L20),MONTH(L20),DAY(L20))) -> 46997 | N20: =IF(K20="","",(DATE(YEAR(K20),MONTH(K20)+2,DAY(K20)))) -> 47027 | O20: =IF(N20="","",(DATE(YEAR(N20),MONTH(N20)+C20,DAY(N20)))) -> 47515 | P20: =IF(O20="","",DATE(YEAR(O20), MONTH(O20)+1,DAY(O20))) -> 47543 | Q20: =IF(O20="","",DATE(YEAR(P20),MONTH(P20),DAY(P20))) -> 47543 | R20: =IF((AND($E20<='LCS San Diego'!R$4,$F20>='LCS San Diego'!R$4)),"P/L",IF((AND($H20<='LCS San Diego'!R$4,$I20>='LCS San Diego'!R$4)),"XO",IF((AND($J20<='LCS San Diego'!R$4,$K20>='LCS San Diego'!R$4)),"3",IF((AND($L20<='LCS San Diego'!R$4,$M20>='LCS San Diego'!R$4)),"C",IF((AND($N20<='LCS San Diego'!R$4,$O20>='LCS San Diego'!R$4)),"CO",IF((AND($P20<='LCS San Diego'!R$4,$Q20>='LCS San Diego'!R$4)),"C",0)))))) -> 0 | S20: =IF((AND($E20<='LCS San Diego'!S$4,$F20>='LCS San Diego'!S$4)),"P/L",IF((AND($H20<='LCS San Diego'!S$4,$I20>='LCS San Diego'!S$4)),"XO",IF((AND($J20<='LCS San Diego'!S$4,$K20>='LCS San Diego'!S$4)),"3",IF((AND($L20<='LCS San Diego'!S$4,$M20>='LCS San Diego'!S$4)),"C",IF((AND($N20<='LCS San Diego'!S$4,$O20>='LCS San Diego'!S$4)),"CO",IF((AND($P20<='LCS San Diego'!S$4,$Q20>='LCS San Diego'!S$4)),"C",0)))))) -> 0 | T20: =IF((AND($E20<='LCS San Diego'!T$4,$F20>='LCS San Diego'!T$4)),"P/L",IF((AND($H20<='LCS San Diego'!T$4,$I20>='LCS San Diego'!T$4)),"XO",IF((AND($J20<='LCS San Diego'!T$4,$K20>='LCS San Diego'!T$4)),"3",IF((AND($L20<='LCS San Diego'!T$4,$M20>='LCS San Diego'!T$4)),"C",IF((AND($N20<='LCS San Diego'!T$4,$O20>='LCS San Diego'!T$4)),"CO",IF((AND($P20<='LCS San Diego'!T$4,$Q20>='LCS San Diego'!T$4)),"C",0)))))) -> 0 | U20: =IF((AND($E20<='LCS San Diego'!U$4,$F20>='LCS San Diego'!U$4)),"P/L",IF((AND($H20<='LCS San Diego'!U$4,$I20>='LCS San Diego'!U$4)),"XO",IF((AND($J20<='LCS San Diego'!U$4,$K20>='LCS San Diego'!U$4)),"3",IF((AND($L20<='LCS San Diego'!U$4,$M20>='LCS San Diego'!U$4)),"C",IF((AND($N20<='LCS San Diego'!U$4,$O20>='LCS San Diego'!U$4)),"CO",IF((AND($P20<='LCS San Diego'!U$4,$Q20>='LCS San Diego'!U$4)),"C",0)))))) -> 0 | V20: =IF((AND($E20<='LCS San Diego'!V$4,$F20>='LCS San Diego'!V$4)),"P/L",IF((AND($H20<='LCS San Diego'!V$4,$I20>='LCS San Diego'!V$4)),"XO",IF((AND($J20<='LCS San Diego'!V$4,$K20>='LCS San Diego'!V$4)),"3",IF((AND($L20<='LCS San Diego'!V$4,$M20>='LCS San Diego'!V$4)),"C",IF((AND($N20<='LCS San Diego'!V$4,$O20>='LCS San Diego'!V$4)),"CO",IF((AND($P20<='LCS San Diego'!V$4,$Q20>='LCS San Diego'!V$4)),"C",0)))))) -> 0 | W20: =IF((AND($E20<='LCS San Diego'!W$4,$F20>='LCS San Diego'!W$4)),"P/L",IF((AND($H20<='LCS San Diego'!W$4,$I20>='LCS San Diego'!W$4)),"XO",IF((AND($J20<='LCS San Diego'!W$4,$K20>='LCS San Diego'!W$4)),"3",IF((AND($L20<='LCS San Diego'!W$4,$M20>='LCS San Diego'!W$4)),"C",IF((AND($N20<='LCS San Diego'!W$4,$O20>='LCS San Diego'!W$4)),"CO",IF((AND($P20<='LCS San Diego'!W$4,$Q20>='LCS San Diego'!W$4)),"C",0)))))) -> 0 | X20: =IF((AND($E20<='LCS San Diego'!X$4,$F20>='LCS San Diego'!X$4)),"P/L",IF((AND($H20<='LCS San Diego'!X$4,$I20>='LCS San Diego'!X$4)),"XO",IF((AND($J20<='LCS San Diego'!X$4,$K20>='LCS San Diego'!X$4)),"3",IF((AND($L20<='LCS San Diego'!X$4,$M20>='LCS San Diego'!X$4)),"C",IF((AND($N20<='LCS San Diego'!X$4,$O20>='LCS San Diego'!X$4)),"CO",IF((AND($P20<='LCS San Diego'!X$4,$Q20>='LCS San Diego'!X$4)),"C",0)))))) -> 0 | Y20: =IF((AND($E20<='LCS San Diego'!Y$4,$F20>='LCS San Diego'!Y$4)),"P/L",IF((AND($H20<='LCS San Diego'!Y$4,$I20>='LCS San Diego'!Y$4)),"XO",IF((AND($J20<='LCS San Diego'!Y$4,$K20>='LCS San Diego'!Y$4)),"3",IF((AND($L20<='LCS San Diego'!Y$4,$M20>='LCS San Diego'!Y$4)),"C",IF((AND($N20<='LCS San Diego'!Y$4,$O20>='LCS San Diego'!Y$4)),"CO",IF((AND($P20<='LCS San Diego'!Y$4,$Q20>='LCS San Diego'!Y$4)),"C",0)))))) -> 0 | ... CL20: =IF((AND($E20<='LCS San Diego'!CL$4,$F20>='LCS San Diego'!CL$4)),"P/L",IF((AND($H20<='LCS San Diego'!CL$4,$I20>='LCS San Diego'!CL$4)),"XO",IF((AND($J20<='LCS San Diego'!CL$4,$K20>='LCS San Diego'!CL$4)),"3",IF((AND($L20<='LCS San Diego'!CL$4,$M20>='LCS San Diego'!CL$4)),"C",IF((AND($N20<='LCS San Diego'!CL$4,$O20>='LCS San Diego'!CL$4)),"CO",IF((AND($P20<='LCS San Diego'!CL$4,$Q20>='LCS San Diego'!CL$4)),"C",0)))))) -> 0
A21: OMAHA (LCS 12) - 20141 | R21: ='LCS San Diego'!$A$2-DAY('LCS San Diego'!$A$2)+1 -> 46054 | S21: =DATE(YEAR(R21),MONTH(R21)+1,DAY(R21)) -> 46082 | T21: =DATE(YEAR(S21),MONTH(S21)+1,DAY(S21)) -> 46113 | U21: =DATE(YEAR(T21),MONTH(T21)+1,DAY(T21)) -> 46143 | V21: =DATE(YEAR(U21),MONTH(U21)+1,DAY(U21)) -> 46174 | W21: =DATE(YEAR(V21),MONTH(V21)+1,DAY(V21)) -> 46204 | X21: =DATE(YEAR(W21),MONTH(W21)+1,DAY(W21)) -> 46235 | Y21: =DATE(YEAR(X21),MONTH(X21)+1,DAY(X21)) -> 46266 | Z21: =DATE(YEAR(Y21),MONTH(Y21)+1,DAY(Y21)) -> 46296 | ... CL21: =DATE(YEAR(CK21),MONTH(CK21)+1,DAY(CK21)) -> 48245
A22: Doyle, Ryan (COC DEC 24 / EARLY JAN 2025) | B22: 17 | C22: 13 | D22: 1 | G22: =F22-E22 -> 0 | H22: 45069 | I22: =IF(H22="",0,DATE(YEAR(H22),MONTH(H22)+B22,DAY(H22))) -> 45588 | J22: =IF(I22="","",(DATE(YEAR(I22),MONTH(I22)+1,DAY(I22)))) -> 45619 | K22: =IF(J22="","",(DATE(YEAR(J22),MONTH(J22)+D22,DAY(J22)))) -> 45649 | L22: =IF(N22="","",DATE(YEAR(N22), MONTH(N22)-1,DAY(N22))) -> 45680 | M22: 45589 | N22: =IF(K22="","",(DATE(YEAR(K22),MONTH(K22)+2,DAY(K22)))) -> 45711 | O22: =IF(N22="","",(DATE(YEAR(N22),MONTH(N22)+C22,DAY(N22)))) -> 46104 | P22: =IF(O22="","",DATE(YEAR(O22), MONTH(O22)+1,DAY(O22))) -> 46135 | Q22: =IF(O22="","",DATE(YEAR(P22),MONTH(P22),DAY(P22))) -> 46135 | R22: =IF((AND($E22<='LCS San Diego'!R$4,$F22>='LCS San Diego'!R$4)),"P/L",IF((AND($H22<='LCS San Diego'!R$4,$I22>='LCS San Diego'!R$4)),"XO",IF((AND($J22<='LCS San Diego'!R$4,$K22>='LCS San Diego'!R$4)),"3",IF((AND($L22<='LCS San Diego'!R$4,$M22>='LCS San Diego'!R$4)),"C",IF((AND($N22<='LCS San Diego'!R$4,$O22>='LCS San Diego'!R$4)),"CO",IF((AND($P22<='LCS San Diego'!R$4,$Q22>='LCS San Diego'!R$4)),"C",0)))))) -> CO | S22: =IF((AND($E22<='LCS San Diego'!S$4,$F22>='LCS San Diego'!S$4)),"P/L",IF((AND($H22<='LCS San Diego'!S$4,$I22>='LCS San Diego'!S$4)),"XO",IF((AND($J22<='LCS San Diego'!S$4,$K22>='LCS San Diego'!S$4)),"3",IF((AND($L22<='LCS San Diego'!S$4,$M22>='LCS San Diego'!S$4)),"C",IF((AND($N22<='LCS San Diego'!S$4,$O22>='LCS San Diego'!S$4)),"CO",IF((AND($P22<='LCS San Diego'!S$4,$Q22>='LCS San Diego'!S$4)),"C",0)))))) -> CO | T22: =IF((AND($E22<='LCS San Diego'!T$4,$F22>='LCS San Diego'!T$4)),"P/L",IF((AND($H22<='LCS San Diego'!T$4,$I22>='LCS San Diego'!T$4)),"XO",IF((AND($J22<='LCS San Diego'!T$4,$K22>='LCS San Diego'!T$4)),"3",IF((AND($L22<='LCS San Diego'!T$4,$M22>='LCS San Diego'!T$4)),"C",IF((AND($N22<='LCS San Diego'!T$4,$O22>='LCS San Diego'!T$4)),"CO",IF((AND($P22<='LCS San Diego'!T$4,$Q22>='LCS San Diego'!T$4)),"C",0)))))) -> 0 | U22: =IF((AND($E22<='LCS San Diego'!U$4,$F22>='LCS San Diego'!U$4)),"P/L",IF((AND($H22<='LCS San Diego'!U$4,$I22>='LCS San Diego'!U$4)),"XO",IF((AND($J22<='LCS San Diego'!U$4,$K22>='LCS San Diego'!U$4)),"3",IF((AND($L22<='LCS San Diego'!U$4,$M22>='LCS San Diego'!U$4)),"C",IF((AND($N22<='LCS San Diego'!U$4,$O22>='LCS San Diego'!U$4)),"CO",IF((AND($P22<='LCS San Diego'!U$4,$Q22>='LCS San Diego'!U$4)),"C",0)))))) -> 0 | V22: =IF((AND($E22<='LCS San Diego'!V$4,$F22>='LCS San Diego'!V$4)),"P/L",IF((AND($H22<='LCS San Diego'!V$4,$I22>='LCS San Diego'!V$4)),"XO",IF((AND($J22<='LCS San Diego'!V$4,$K22>='LCS San Diego'!V$4)),"3",IF((AND($L22<='LCS San Diego'!V$4,$M22>='LCS San Diego'!V$4)),"C",IF((AND($N22<='LCS San Diego'!V$4,$O22>='LCS San Diego'!V$4)),"CO",IF((AND($P22<='LCS San Diego'!V$4,$Q22>='LCS San Diego'!V$4)),"C",0)))))) -> 0 | W22: =IF((AND($E22<='LCS San Diego'!W$4,$F22>='LCS San Diego'!W$4)),"P/L",IF((AND($H22<='LCS San Diego'!W$4,$I22>='LCS San Diego'!W$4)),"XO",IF((AND($J22<='LCS San Diego'!W$4,$K22>='LCS San Diego'!W$4)),"3",IF((AND($L22<='LCS San Diego'!W$4,$M22>='LCS San Diego'!W$4)),"C",IF((AND($N22<='LCS San Diego'!W$4,$O22>='LCS San Diego'!W$4)),"CO",IF((AND($P22<='LCS San Diego'!W$4,$Q22>='LCS San Diego'!W$4)),"C",0)))))) -> 0 | X22: =IF((AND($E22<='LCS San Diego'!X$4,$F22>='LCS San Diego'!X$4)),"P/L",IF((AND($H22<='LCS San Diego'!X$4,$I22>='LCS San Diego'!X$4)),"XO",IF((AND($J22<='LCS San Diego'!X$4,$K22>='LCS San Diego'!X$4)),"3",IF((AND($L22<='LCS San Diego'!X$4,$M22>='LCS San Diego'!X$4)),"C",IF((AND($N22<='LCS San Diego'!X$4,$O22>='LCS San Diego'!X$4)),"CO",IF((AND($P22<='LCS San Diego'!X$4,$Q22>='LCS San Diego'!X$4)),"C",0)))))) -> 0 | Y22: =IF((AND($E22<='LCS San Diego'!Y$4,$F22>='LCS San Diego'!Y$4)),"P/L",IF((AND($H22<='LCS San Diego'!Y$4,$I22>='LCS San Diego'!Y$4)),"XO",IF((AND($J22<='LCS San Diego'!Y$4,$K22>='LCS San Diego'!Y$4)),"3",IF((AND($L22<='LCS San Diego'!Y$4,$M22>='LCS San Diego'!Y$4)),"C",IF((AND($N22<='LCS San Diego'!Y$4,$O22>='LCS San Diego'!Y$4)),"CO",IF((AND($P22<='LCS San Diego'!Y$4,$Q22>='LCS San Diego'!Y$4)),"C",0)))))) -> 0 | ... CL22: =IF((AND($E22<='LCS San Diego'!CL$4,$F22>='LCS San Diego'!CL$4)),"P/L",IF((AND($H22<='LCS San Diego'!CL$4,$I22>='LCS San Diego'!CL$4)),"XO",IF((AND($J22<='LCS San Diego'!CL$4,$K22>='LCS San Diego'!CL$4)),"3",IF((AND($L22<='LCS San Diego'!CL$4,$M22>='LCS San Diego'!CL$4)),"C",IF((AND($N22<='LCS San Diego'!CL$4,$O22>='LCS San Diego'!CL$4)),"CO",IF((AND($P22<='LCS San Diego'!CL$4,$Q22>='LCS San Diego'!CL$4)),"C",0)))))) -> 0
A23: Nottberg, Adam (24-2)(D.I.T.) (2412) | B23: 14 | C23: 17 | D23: 1 | G23: =F23-E23 -> 0 | H23: 45620 | I23: =IF(H23="",0,DATE(YEAR(H23),MONTH(H23)+B23,DAY(H23))) -> 46046 | J23: =IF(I23="","",(DATE(YEAR(I23),MONTH(I23)+1,DAY(I23)))) -> 46077 | K23: =IF(J23="","",(DATE(YEAR(J23),MONTH(J23)+D23,DAY(J23)))) -> 46105 | L23: =IF(N23="","",DATE(YEAR(N23), MONTH(N23)-1,DAY(N23))) -> 46136 | M23: =IF(N23="","",DATE(YEAR(L23),MONTH(L23),DAY(L23))) -> 46136 | N23: =IF(K23="","",(DATE(YEAR(K23),MONTH(K23)+2,DAY(K23)))) -> 46166 | O23: =IF(N23="","",(DATE(YEAR(N23),MONTH(N23)+C23,DAY(N23)))) -> 46684 | P23: =IF(O23="","",DATE(YEAR(O23), MONTH(O23)+1,DAY(O23))) -> 46715 | Q23: =IF(O23="","",DATE(YEAR(P23),MONTH(P23),DAY(P23))) -> 46715 | R23: =IF((AND($E23<='LCS San Diego'!R$4,$F23>='LCS San Diego'!R$4)),"P/L",IF((AND($H23<='LCS San Diego'!R$4,$I23>='LCS San Diego'!R$4)),"XO",IF((AND($J23<='LCS San Diego'!R$4,$K23>='LCS San Diego'!R$4)),"3",IF((AND($L23<='LCS San Diego'!R$4,$M23>='LCS San Diego'!R$4)),"C",IF((AND($N23<='LCS San Diego'!R$4,$O23>='LCS San Diego'!R$4)),"CO",IF((AND($P23<='LCS San Diego'!R$4,$Q23>='LCS San Diego'!R$4)),"C",0)))))) -> 0 | S23: =IF((AND($E23<='LCS San Diego'!S$4,$F23>='LCS San Diego'!S$4)),"P/L",IF((AND($H23<='LCS San Diego'!S$4,$I23>='LCS San Diego'!S$4)),"XO",IF((AND($J23<='LCS San Diego'!S$4,$K23>='LCS San Diego'!S$4)),"3",IF((AND($L23<='LCS San Diego'!S$4,$M23>='LCS San Diego'!S$4)),"C",IF((AND($N23<='LCS San Diego'!S$4,$O23>='LCS San Diego'!S$4)),"CO",IF((AND($P23<='LCS San Diego'!S$4,$Q23>='LCS San Diego'!S$4)),"C",0)))))) -> 3 | T23: =IF((AND($E23<='LCS San Diego'!T$4,$F23>='LCS San Diego'!T$4)),"P/L",IF((AND($H23<='LCS San Diego'!T$4,$I23>='LCS San Diego'!T$4)),"XO",IF((AND($J23<='LCS San Diego'!T$4,$K23>='LCS San Diego'!T$4)),"3",IF((AND($L23<='LCS San Diego'!T$4,$M23>='LCS San Diego'!T$4)),"C",IF((AND($N23<='LCS San Diego'!T$4,$O23>='LCS San Diego'!T$4)),"CO",IF((AND($P23<='LCS San Diego'!T$4,$Q23>='LCS San Diego'!T$4)),"C",0)))))) -> 0 | U23: =IF((AND($E23<='LCS San Diego'!U$4,$F23>='LCS San Diego'!U$4)),"P/L",IF((AND($H23<='LCS San Diego'!U$4,$I23>='LCS San Diego'!U$4)),"XO",IF((AND($J23<='LCS San Diego'!U$4,$K23>='LCS San Diego'!U$4)),"3",IF((AND($L23<='LCS San Diego'!U$4,$M23>='LCS San Diego'!U$4)),"C",IF((AND($N23<='LCS San Diego'!U$4,$O23>='LCS San Diego'!U$4)),"CO",IF((AND($P23<='LCS San Diego'!U$4,$Q23>='LCS San Diego'!U$4)),"C",0)))))) -> 0 | V23: =IF((AND($E23<='LCS San Diego'!V$4,$F23>='LCS San Diego'!V$4)),"P/L",IF((AND($H23<='LCS San Diego'!V$4,$I23>='LCS San Diego'!V$4)),"XO",IF((AND($J23<='LCS San Diego'!V$4,$K23>='LCS San Diego'!V$4)),"3",IF((AND($L23<='LCS San Diego'!V$4,$M23>='LCS San Diego'!V$4)),"C",IF((AND($N23<='LCS San Diego'!V$4,$O23>='LCS San Diego'!V$4)),"CO",IF((AND($P23<='LCS San Diego'!V$4,$Q23>='LCS San Diego'!V$4)),"C",0)))))) -> CO | W23: =IF((AND($E23<='LCS San Diego'!W$4,$F23>='LCS San Diego'!W$4)),"P/L",IF((AND($H23<='LCS San Diego'!W$4,$I23>='LCS San Diego'!W$4)),"XO",IF((AND($J23<='LCS San Diego'!W$4,$K23>='LCS San Diego'!W$4)),"3",IF((AND($L23<='LCS San Diego'!W$4,$M23>='LCS San Diego'!W$4)),"C",IF((AND($N23<='LCS San Diego'!W$4,$O23>='LCS San Diego'!W$4)),"CO",IF((AND($P23<='LCS San Diego'!W$4,$Q23>='LCS San Diego'!W$4)),"C",0)))))) -> CO | X23: =IF((AND($E23<='LCS San Diego'!X$4,$F23>='LCS San Diego'!X$4)),"P/L",IF((AND($H23<='LCS San Diego'!X$4,$I23>='LCS San Diego'!X$4)),"XO",IF((AND($J23<='LCS San Diego'!X$4,$K23>='LCS San Diego'!X$4)),"3",IF((AND($L23<='LCS San Diego'!X$4,$M23>='LCS San Diego'!X$4)),"C",IF((AND($N23<='LCS San Diego'!X$4,$O23>='LCS San Diego'!X$4)),"CO",IF((AND($P23<='LCS San Diego'!X$4,$Q23>='LCS San Diego'!X$4)),"C",0)))))) -> CO | Y23: =IF((AND($E23<='LCS San Diego'!Y$4,$F23>='LCS San Diego'!Y$4)),"P/L",IF((AND($H23<='LCS San Diego'!Y$4,$I23>='LCS San Diego'!Y$4)),"XO",IF((AND($J23<='LCS San Diego'!Y$4,$K23>='LCS San Diego'!Y$4)),"3",IF((AND($L23<='LCS San Diego'!Y$4,$M23>='LCS San Diego'!Y$4)),"C",IF((AND($N23<='LCS San Diego'!Y$4,$O23>='LCS San Diego'!Y$4)),"CO",IF((AND($P23<='LCS San Diego'!Y$4,$Q23>='LCS San Diego'!Y$4)),"C",0)))))) -> CO | ... CL23: =IF((AND($E23<='LCS San Diego'!CL$4,$F23>='LCS San Diego'!CL$4)),"P/L",IF((AND($H23<='LCS San Diego'!CL$4,$I23>='LCS San Diego'!CL$4)),"XO",IF((AND($J23<='LCS San Diego'!CL$4,$K23>='LCS San Diego'!CL$4)),"3",IF((AND($L23<='LCS San Diego'!CL$4,$M23>='LCS San Diego'!CL$4)),"C",IF((AND($N23<='LCS San Diego'!CL$4,$O23>='LCS San Diego'!CL$4)),"CO",IF((AND($P23<='LCS San Diego'!CL$4,$Q23>='LCS San Diego'!CL$4)),"C",0)))))) -> 0
